Workbook

Sheet USDKRW
A1: Base Date | B1: Release Date | C1: Time | D1: Time Zone | E1: Body | F1: Title | G1: Researcher | H1: USDKRW Lower | I1: USDKRW Upper | J1: USDKRW Median | K1: USDKRW Range | L1: EURKRW Lower | M1: EURKRW Upper | N1: EURKRW Median | O1: EURKRW Range | P1: JPYKRW Lower | Q1: JPYKRW Upper | R1: JPYKRW Median | S1: JPYKRW Range | T1: CNYKRW Lower | U1: CNYKRW Upper | V1: CNYKRW Median | W1: CNYKRW Range
A2: 42738 | B2: 42738 | C2: 0.36805556 | D2: UTC+9 | E2: • 달러/원 환율은 전일 대비 0.30 원 상승한 1208.00 원으로 마감. • 달러/원 환율은 역외시장을 반영하여 전일대비 1.70 원 하락한 1,206.00 원에 출발. 달러화 강세에 대한 전망에 매수가 꾸준히 지속되는 양상이었지만 주요국 금융시장이 휴장으로 인해 달러화는 제한된 흐름을 보였음. 이월 수출 매도 물량과 저점 매수 수요가 섞이면서 달러/원 환율은 전일 대비 0.30 원 상승한 1,208.00 원으로 마감. • 역외 NDF 시장은 1207.50 원 (전 거래일 종가대비 0.20 원 하락) 마감. • 금일 달러/원 환율은 12 월 FOMC 의사록 내용과 비농업 부문 고용자 수 등 미국 경제 지표가 금주에 발표됨에 따라 관망세 지속될 것으로 전망되며, 위안화 절하 지속에 따른 중국발 금융불안 우려로 달러화는 강세 이어갈 것으로 예상. 다만 1,200 원대 레벨에 대한 부담과 수출업체의 이월 매도물량으로 인해 상승폭은 제한될 것으로 보임. 달러/원: 1,203~1,217 원 엔/원: 1,016~1,035 원 유로/원: 1,251~1,270 원 | F2: Daily FX Market Commentary (2017. 01. 03) | J2: =IFERROR(AVERAGE(H2:I2),"") | K2: =IFERROR(I2-H2,"") -> 0
A3: 42739 | B3: 42739 | C3: 0.36805556 | D3: UTC+9 | E3: • 달러/원 환율은 전일 대비 4.50 원 하락한 1203.50 원으로 마감. • 달러/원 환율은 역외시장을 반영하여 전일 대비 1.50 원 상승한 1,209.50 원에 출발. 장 초반 1,210 원선을 돌파했으나 중국 제조업 구매관리자 지수(PMI) 호조에 따른 위안화 강세에 연동되며 레벨을 낮추었음. 장중 일부 롱스탑도 유발되면서 달러화는 하락폭을 키우며 전일 대비 4.50 원 하락한 1203.50 원으로 마감. • 역외 NDF 시장은 1207.30 원 (전 거래일 종가대비 1.20 원 하락) 마감. • 금일 달러/원 환율은 미국 건설, 제조업 경제지표 호조 등으로 연방준비제도(Fed)의 기준금리 인상 기대가 높아진 데에 따른 매수세에 힘입어 상승 출발 예상. 하지만 수입업체 이월 매도 물량 및 고점 매도 수요로 인해 상승폭은 제한될 것으로 보임. 달러/원: 1,198~1,213 원 엔/원: 1,012~1,032 원 유로/원: 1,244~1,264 원 | F3: Daily FX Market Commentary (2017. 01. 04) | J3: =IFERROR(AVERAGE(H3:I3),"") | K3: =IFERROR(I3-H3,"") -> 0
A4: 42740 | B4: 42740 | C4: 0.36805556 | D4: UTC+9 | E4: • 달러/원 환율은 전일 대비 2.90 원 상승한 1206.40 원으로 마감. • 달러/원 환율은 역외시장을 반영하여 전일 대비 3.00 원 상승한 1,206.00 원에 출발. 장 초반 역외투자자의 달러 매수로 1,205 원대를 전후해 지지되다 달러/엔 환율이 오르면서 1,209 원대로 레벨을 높였음. 그러나 1,210 원선 부근에서는 고점인식으로 달러 매수세 감소하여 전일 대비 2.90 원 상승한 1206.40 원으로 마감. • 역외 NDF 시장은 1195.50 원 (전 거래일 종가대비 10.85 원 하락) 마감. • 금일 달러/원 환율은 예상보다 매파적이지 않은 지난해 12 월 연방공개시장위원회(FOMC) 정례회의 의사록 발표 결과 및 위안화 급등으로 인해 하락 출발 예상. 그러나 의사록이 미국경제 추가 성장이 나타날 것이라는 긍정적인 전망을 강화했고, 새 정부 정책에 따른 경제개선 기대가 지속되고 있어 하락세는 제한될 것으로 전망됨. 달러/원: 1,186~1,201 원 엔/원: 1,012~1,032 원 유로/원: 1,247~1,267 원 | F4: Daily FX Market Commentary (2017. 01. 05) | J4: =IFERROR(AVERAGE(H4:I4),"") | K4: =IFERROR(I4-H4,"") -> 0
A5: 42741 | B5: 42741 | C5: 0.36805556 | D5: UTC+9 | E5: • 달러/원 환율은 전일 대비 20.10 원 하락한 1186.30 원으로 마감. • 달러/원 환율은 역외시장을 반영하여 전일 대비 11.40 원 하락한 1,195.00 원에 출발. 미국 연준이 12 월 FOMC 의사록에서 도널드 트럼프 신행정부의 정책에 따른 불확실성에 무게를 실으면서 1,190 원선 부근으로 급격히 하락하였음. 오후 달러/위안 환율에 연동해 추가하락하며 전일 대비 20.10 원 하락한 1186.30 원으로 마감. • 역외 NDF 시장은 1183.70 원 (전 거래일 종가대비 2.6 원 하락) 마감. • 금일 달러/원 환율은 ADP 민간고용이 시장 예상보다 부진함에 따라 10 년 만기 미 국채수익률이 하락하면서 하락 출발 예상. 위안화의 강세 영향도 달러화 하락을 부추기는 요인으로 작용할 것으로 전망됨. 하지만 급락에 따른 저점 결제수요로 인해 하락은 제한될 것으로 예상. 달러/원: 1,174~1,189 원 엔/원: 1,019~1,039 원 유로/원: 1,249~1,269 원 | F5: Daily FX Market Commentary (2017. 01. 06) | J5: =IFERROR(AVERAGE(H5:I5),"") | K5: =IFERROR(I5-H5,"") -> 0
A6: 42744 | B6: 42744 | C6: 0.36805556 | D6: UTC+9 | E6: • 달러/원 환율은 전일 대비 6.70 원 상승한 1193.00 원으로 마감. • 달러/원 환율은 역외시장을 반영하여 전일 대비 2.80 원 내린 1,183.50 원에 출발. 단기 급락에 대한 심리적 저항이 강하게 나타나면서 1,180 원대는 탄탄히 지지되었고, 수입업체 저점 결제수요 및 위안화 약세 전환에 따라 달러 매수가 주를 이루며 달러화는 전일 대비 6.70 원 상승한 1193.00 원으로 마감. • 역외 NDF 시장은 1202.75 원 (전 거래일 종가대비 9.65 원 상승) 마감. • 금일 달러/원 환율은 12 월 고용 지표 내용 중 물가 상승 압력 가중에 주목해 10 년 만기 미 국채수익률이 상승함에 따라 상승 출발 예상. 또한 금주 연준 인사들의 연설, 경제지표 발표 대기 등이 변동성을 확대시킬 수 있음에 유의할 필요 있음. 하지만 그간 달러화 강세를 이끌어왔던 트럼프 정책에 불확실성이 많고 효과를 발휘하기까지 시간이 소요될 것이라는 우려로 인해 상승은 제한될 것으로 예상. 달러/원: 1,196~1,211 원 엔/원: 1,015~1,034 원 유로/원: 1,254~1,273 원 | F6: Daily FX Market Commentary (2017. 01. 09) | J6: =IFERROR(AVERAGE(H6:I6),"") | K6: =IFERROR(I6-H6,"") -> 0
A7: 42745 | B7: 42745 | C7: 0.36805556 | D7: UTC+9 | E7: • 달러/원 환율은 전일 대비 15.30 원 상승한 1,208.30 원으로 마감. • 달러/원 환율은 역외시장을 반영하여 전일 대비 9.00 원 오른 1,202.00 원에 출발. 개장 직후 1,201.00 원을 저점으로 달러/위안 환율 상승에 힘입어 지속 상승하였음. 1,205 원선에서는 수출업체 매도 물량으로 상승폭이 제한되는 듯 하였으나 장 후반에도 꾸준한 매수세 유입으로 달러/원 환율은 전일 대비 15.30 원 상승한 1208.30 원으로 마감. • 역외 NDF 시장은 1203.50 원 (전 거래일 종가대비 4.80 원 하락) 마감. • 금일 달러/원 환율은 ‘하드 브렉시트’우려, 중국 위안화 불안 등으로 인해 강해진 글로벌 안전자산 선호심리 및 유가 하락으로 물가 우려가 약화되어 미국 국채수익률이 내린 영향으로 하락 출발 예상. 다만 이번 주 트럼프 미 대통령 당선인의 기자회견 및 옐런 의장의 연설을 앞두고 관망세 예상되며, 위안화 환율 약세 고시로 하락은 제한될 것으로 예상. 달러/원: 1,194~1,209 원 엔/원: 1,030~1,048 원 유로/원: 1,265~1,284 원 | F7: Daily FX Market Commentary (2017. 01. 10) | J7: =IFERROR(AVERAGE(H7:I7),"") | K7: =IFERROR(I7-H7,"") -> 0
A8: 42746 | B8: 42746 | C8: 0.36805556 | D8: UTC+9 | E8: • 달러/원 환율은 전일 대비 13.70 원 하락한 1,194.60 원으로 마감. • 달러/원 환율은 역외시장을 반영하여 전일 대비 5.80 원 하락한 1,202.50 원에 출발. 미국 연방준비제도(Fed) 위원들의 발언이 그다지 금리인상에 무게를 싣지 않으면서 달러 매도가 우위를 보였고, 1,200 원선 부근에서 지지 되는 듯 하였으나 달러/위안 환율이 상승폭을 줄이면서 달러/원 환율은 1,200 원선 밑으로 하락폭을 키우며 전일 대비 13.70 원 하락한 1,194.60 원으로 마감. 금일예상 • 역외 NDF 시장은 1201.50 원 (전 거래일 종가대비 6.85 원 상승) 마감. • 금일 달러/원 환율은 밤사이 뛰어오른 달러/위안 환율에 연동해 상승 출발 예상. 다만 도널드 트럼프 대통령 당선인의 기자회견에서 세부 정책 내용을 확인하고 가자는 심리로 관망세 예상되며, 최근의 변동성에 대한 부담 및 관망세에 따른 포지션 정리성 매도 물량으로 인해 상승은 제한 될 것으로 예상. 예상범위 달러/원: 1,195~1,210 원 엔/원: 1,028~1,047 원 유로/원: 1,259~1,278 원 | F8: Daily FX Market Commentary (2017. 01. 06) | J8: =IFERROR(AVERAGE(H8:I8),"") | K8: =IFERROR(I8-H8,"") -> 0
A9: 42747 | B9: 42747 | C9: 0.36805556 | D9: UTC+9 | J9: =IFERROR(AVERAGE(H9:I9),"") | K9: =IFERROR(I9-H9,"") -> 0
A10: 42748 | B10: 42748 | C10: 0.36805556 | D10: UTC+9 | J10: =IFERROR(AVERAGE(H10:I10),"") | K10: =IFERROR(I10-H10,"") -> 0
A11: 42749 | B11: 42749 | C11: 0.36805556 | D11: UTC+9 | J11: =IFERROR(AVERAGE(H11:I11),"") | K11: =IFERROR(I11-H11,"") -> 0
A12: 42750 | B12: 42750 | C12: 0.36805556 | D12: UTC+9 | J12: =IFERROR(AVERAGE(H12:I12),"") | K12: =IFERROR(I12-H12,"") -> 0
A13: 42751 | B13: 42751 | C13: 0.36805556 | D13: UTC+9 | J13: =IFERROR(AVERAGE(H13:I13),"") | K13: =IFERROR(I13-H13,"") -> 0
A14: 42752 | B14: 42752 | C14: 0.36805556 | D14: UTC+9 | J14: =IFERROR(AVERAGE(H14:I14),"") | K14: =IFERROR(I14-H14,"") -> 0
A15: 42753 | B15: 42753 | C15: 0.36805556 | D15: UTC+9 | J15: =IFERROR(AVERAGE(H15:I15),"") | K15: =IFERROR(I15-H15,"") -> 0
A16: 42754 | B16: 42754 | C16: 0.36805556 | D16: UTC+9 | J16: =IFERROR(AVERAGE(H16:I16),"") | K16: =IFERROR(I16-H16,"") -> 0
A17: 42755 | B17: 42755 | C17: 0.36805556 | D17: UTC+9 | J17: =IFERROR(AVERAGE(H17:I17),"") | K17: =IFERROR(I17-H17,"") -> 0
A18: 42756 | B18: 42756 | C18: 0.36805556 | D18: UTC+9 | J18: =IFERROR(AVERAGE(H18:I18),"") | K18: =IFERROR(I18-H18,"") -> 0
A19: 42757 | B19: 42757 | C19: 0.36805556 | D19: UTC+9 | J19: =IFERROR(AVERAGE(H19:I19),"") | K19: =IFERROR(I19-H19,"") -> 0
A20: 42758 | B20: 42758 | C20: 0.36805556 | D20: UTC+9 | J20: =IFERROR(AVERAGE(H20:I20),"") | K20: =IFERROR(I20-H20,"") -> 0
... A3134: 45872 | B3134: 45872 | C3134: 0.36805556 | D3134: UTC+9 | J3134: =IFERROR(AVERAGE(H3134:I3134),"") | K3134: =IFERROR(I3134-H3134,"") -> 0
A3135: 45873 | B3135: 45873 | C3135: 0.36805556 | D3135: UTC+9 | E3135: [달러/원 환율] 고용 쇼크에 하락 개장, 외국인 자금 흐름 주시하며 등락 전일 달러/원 환율은 한미 협상 타결에 따른 불확실성 해소에도 불구하고, 미 달러화 강세에 연동하며 상방 흐름. 이후 국내 세법 개정안 공개로 인한 국내 주식시장 급락 및 외국인 주식 대량 매도에 환율 추가 상승. 5월 이후 처음으로 빅 피겨인 1,400원 상회, 전일 종가 대비 14.4원 상승한 1,401.4원에 정규장 마감. 야간장에서는 미국 7월 고용지표 예상 하회에 따른 달러 약세에 하락하며 1,386.5원에 마감. 역외 NDF 환율은 12.70원 하락한 1,386.50원에 최종 호가 금일 달러/원 환율은 주말간 달러 약세와 역외 거래를 감안해 1,390원 부근에서 하락 개장 예상. 미국 고용 쇼크로 달러 가치가 급락하며 달러/원 하방에 기여. 다만 관세로 인한 한국 수출 둔화 우려와 정부 세제 개편안 실망에 따른 국내증시 부진은 원화에 부정적. 금일 환율은 글로벌 약 달러 속 하락 개장한 뒤, 외국인의 국내주식 매매 동향 주시하며 등락. 환율 하단은 20일 이동평균선인 1,383원 부근에 형성될 전망 [글로벌 동향] 미국 고용 쇼크에 달러 급락, 연준 9월 금리인하 기대 확산 전일 미 달러화는 미국 핵심 고용지표 둔화에 약세 전환. 주요 6개국 통화로 구성된 달러화 지수는 1.35% 급락한 98.70pt 기록. 미국 노동부에 따르면, 7월 비농업 부문 고용은 전월대비 7만 3천명 증가에 그치며 예상치 (+10.4만명)를 큰 폭으로 하회. 기존 5월 및 6월 고용 수치는 25만 8천명 하향 조정 (각각 12만 5천명, 13만 3천명). 7월 실업률은 4.2%로 전월치 대비 0.1%p 소폭 상승. 고용 외에도 제조업 업황 및 소비심리 약화도 확인. 공급관리협회 (ISM)의 7월 제조업 구매관리자지수 (PMI)는 48.0pt로 예상치 (49.5pt) 및 전월치 (49.0pt) 모두 하회. 미시건대 조사에 따르면, 7월 소비자심리지수는 61.7pt로 전월대비 1.0pt 상승했지만 예상치 (62.0pt) 하회. 미국 고용, 제조업 및 소비 심리의 부진이 확인되자 연준의 9월 금리인하 기대 급부상. 선물시장에 반영된 9월 인하 확률은 기존 37.7%에서 89.8%로 급등 (FedWatch) [마켓 이슈] 관세 여진 한동안 지속, 수출에 미칠 부정적 영향이 우려 사항 7월 31일 한미 무역협상이 극적으로 타결되며 그간 시장을 지배했던 관세 불확실성은 상당 부분 해소. 협상으로 인해 관세율이 당초 우려했던 것보다 낮아진 점도 긍정적인 부분 (상호 관세율 25%→15%). 하지만 그동안 한미 자유무역협정 (FTA)으로 제로 수준이었던 관세율이 올해부터 새로 생겨난 부분은 한국 수출에 부정적 영향을 미칠 전망. 미국의 한국산 수입품에 대한 실효 관세율은 지난해 5월 0.2%에서 올해 5월 12.3%로 11.1%p나 급등. 우리나라의 올해 7월 수출액이 608.2억 달러로 전년대비 5.9% 증가하며 역대 7월 중 최대치를 기록했지만, 상호 관세가 본격적으로 발효되는 8월부터는 수출이 둔화할 것으로 예상. 수출은 국내 경제성장 (펀더멘털) 및 달러 수급 여건에 영향을 미치는 요인. 즉 향후 수출 부진으로 인해 성장 여건이 약화하거나 달러 공급이 감소한다면 원화 약세가 자극될 가능성 | F3135: 펄펄 끓던 달러/원, 고용 쇼크에 급랭 [금일 달러/원 환율 1,383~1,391원 전망] | G3135: 이민혁 | H3135: 1383 | I3135: 1391 | J3135: =IFERROR(AVERAGE(H3135:I3135),"") -> 1387 | K3135: =IFERROR(I3135-H3135,"") -> 8
A3136: 45874 | B3136: 45874 | C3136: 0.36805556 | D3136: UTC+9 | E3136: [달러/원 환율] 반발 매수에도 고용 여파에 하방 우세, 70원대 진입 시도 전일 달러/원 환율은 미국 고용 쇼크에 따른 달러 약세에 1,390원으로 하락 개장한 뒤, 추격 네고물량 출회하며 1,380원대 진입. 이후 역외 달러 매도까지 겹치며 추가 하락했으나 20일 이동평균선 1,383원 부근에서 저점 매수 유입되며 하단 지지, 전일 종가 대비 16.2원 하락한 1,385.2원에 정규장 마감. 야간장에서는 정규장 급락에 따른 반발 매수세에 소폭 상승하며 1,386.5원에 마감. 역외 NDF 환율은 0.15원 상승한 1,383.00원에 최종 호가 금일 달러/원 환율은 간밤 달러 약세와 역외 거래를 감안해 1,380원대 초중반 하락 개장 예상. 미국 고용 여파가 이어지며 연준 인하 기대 확산. 이에 따른 달러 약세가 달러/원 하락 압력으로 작용. 다만 단기간 급락에 따른 반발 매수가 하단 지지. 20일 이동평균선인 1,383원 하회 여부가 관건이며, 하회 시 50일 이평선인 1,373원이 다음 지지선. 1차 지지선 하회 실패 시 환율은 1,380원대 중반 보합권 등락 전망 [글로벌 동향] 고용 여파 지속, 연준 연내 3회 인하 기대 등에 달러 약세 전일 미 달러화는 미국 고용 충격 여진이 이어지는 가운데, 반발 매수에 강보합. 주요 6개국 통화로 구성된 달러화 지수는 0.05% 소폭 상승한 98.75pt 기록. 전주 발표된 미국 비농업 고용자수 하향 조정 여파에 연준 9월 금리인하 확률은 94.4%까지 상승 (FedWatch). 금리 선물시장에서는 연준의 연내 2.5회 인하, 즉 올해 남은 3차례 회의에서 모두 인하에 나설 가능성도 일부 반영 중. 샌프란시스코 연은의 메리 데일리 총재는 올해 금리를 두 번 '이상' 인하해야 할 수도 있다고 언급하며 3회 인하 기대 자극. 이에 미 장단기 국채금리가 이틀 연속 하락하며 달러 약세에 일조. 국제유가 급락도 달러 약세에 일부 기여. OPEC+가 9월부터 일일 54.7만 배럴 규모 증산에 합의하며 국제유가 (WTI 근월물)는 1.54% 급락한 배럴당 66.29달러에 거래. 한편 유럽연합 (EU)은 대미 관세 보복조치를 6개월 유예한다고 발표 [마켓 이슈] 연준 금리 기대로 살펴본 달러/원, 25bp 낮아지면 30원 하락 지난주 미국 비농업 고용 (Nonfarm Payroll) 지표가 큰 폭으로 하향 조정되며 연준 9월 금리인하 기대 확산. FedWatch에서는 9월 인하 확률을 94.4%로 반영 중. 달러 향방에 있어서 연준의 인하 재개 시점보다는 인하 사이클의 깊이, 즉 중기 시계에서의 금리인하 폭이 관건. 미 달러화 지수 및 연준의 26년말 금리 기대치 간의 상관계수는 +0.86이며, 현재 달러화 지수는 26년말까지 약 5회 정도의 금리인하 기대를 반영 중. 앞으로 발표될 미국 지표에서 실물경기 둔화에 대한 추가 증거가 확인된다면, 연준의 인하 기대는 더욱 확산하고 달러 약세는 가속화할 전망. 한편 다른 조건이 일정할 때 금리 기대치 25bp 하락 시 달러화 지수는 3.75pt 하락하고, 달러화 지수 1pt 하락 시 달러/원 환율은 7.5원 하락하는 관계 고려 (regression). 26년말까지 연준 6회 인하 기대 형성 시, 달러/원은 약 30원 정도 하락 압력이 있는 것으로 추정 (3.75pt*7.5원) | F3136: 9월 금리인하 캘박, 관건은 추가 인하 캐파 [금일 달러/원 환율 1,373~1,390원 전망] | G3136: 이민혁 | H3136: 1373 | I3136: 1390 | J3136: =IFERROR(AVERAGE(H3136:I3136),"") -> 1381.5 | K3136: =IFERROR(I3136-H3136,"") -> 17
A3137: 45875 | B3137: 45875 | C3137: 0.36805556 | D3137: UTC+9 | E3137: [달러/원 환율] 달러 혼조 및 수급 노이즈에 하방 제약, 1,380원대 등락 전일 달러/원 환율은 미국 고용 충격에 따른 달러 약세에 1,384원으로 하락 개장한 뒤 20일 이동평균선인 1,383원을 유의미하게 하회하지 못하며 반등 시도. 외국인의 주식 순매수에도 불구, 달러 반등 및 반발 매수세에 상승 흐름 이어지며 장중 1,390원 상회. 이후 고점 매도에 조정되며 전일 종가 대비 3.1원 상승한 1,388.3원에 정규장 마감. 야간장에서는 미국 서비스업 PMI 예상 하회에 따른 약 달러에 1,386.3원에 마감. 역외 NDF 환율은 1.35원 하락한 1,384.65원에 최종 호가 금일 달러/원 환율은 간밤 달러 흐름과 역외 거래를 감안해 1,380원대 중반 보합권 개장 예상. 미국 서비스업 회복세 둔화에도 물가상승 등 스태그플레이션 조짐에 달러 혼조. 이에 달러/원도 뚜렷한 방향성 갖고 움직이긴 어려운 장세. 더불어 국내외 증시 측면에서의 자금 유출 등 수급 노이즈는 환율 하방을 제약하는 요소. 금일 환율은 전일장과 유사한 레인지에서 등락 예상 (1,382~1,392원) [글로벌 동향] 미국 서비스업 PMI 예상 하회, 스태그플레이션 조짐 포착 전일 미 달러화는 반발 매수세에도 불구하고 서비스 업황 둔화 조짐에 강보합. 주요 6개국 통화로 구성된 달러화 지수는 0.02% 소폭 상승한 98.76pt 기록. 공급관리협회 (ISM)에 따르면, 7월 서비스업 구매관리자지수 (PMI)는 50.1pt를 기록하며 확장세는 유지했지만, 예상치 (51.5pt) 및 전월치 (50.8pt)는 하회. 세부 항목별로 고용지수는 전월대비 0.8pt 하락한 46.4pt, 가격지수는 2.4pt 상승한 69.9pt를 기록하며 서비스 부문에서 스태그플레이션 조짐 포착. ISM 관계자는 고금리와 관세 부담으로 서비스업 회복세가 불안정한 상태라고 평가. 미 국채금리는 스태그플레이션 조짐에 장단기물 혼조, 뉴욕증시는 경기침체 가능성 반영하며 3대 지수 하락. 한편 트럼프 대통령은 사임한 쿠글러 이사의 후임을 이번 주 내로 결정할 것이며, 후보는 2~3명이라고 언급. 더불어 차기 연준 의장 후보는 총 4명이라고 덧붙임 [마켓 이슈] 관세 여파, 연준 인하 기대, 세제 개편안 실망에 수급 변화 조짐 한국 무역수지와 내외국인 주식 순투자 금액으로 측정한 달러 수지는 3개월 연속 흑자, 즉 달러 유입 규모가 유출 규모를 상회. 수출 호조로 무역흑자 기조가 이어진 가운데, 대선 전후 외국인의 국내 증시 복귀 및 상대적으로 부진했던 미국 증시에서 내국인의 자금 회수가 발생했기 때문. 달러 순유입으로 인해 같은 기간 달러/원 환율의 레벨도 1,400원대에서 1,300원대로 하락. 하지만 8월부터는 달러 수급 여건의 변화가 감지. 곧 발효될 미국 상호 관세로 인해 수출 둔화 불가피, 이에 따라 무역흑자 폭이 축소될 가능성. 연준 9월 금리인하 기대로 미국 증시가 호조를 보임에 따라 내국인 투자자의 달러 수요도 증가. 여기에 만약 국내 세제 개편안 실망감이 지속되며 외국인 국내 증시 자금까지 빠져나간다면, 달러의 순유입 규모가 줄어들거나 오히려 순유출로 전환할 가능성. 이 경우 환율 하방 제약 (순유입 감소) 또는 상승 전환 (순유출 전환)도 가능 | F3137: 달러/원에 잔뜩 껴있는 수급 노이즈 [금일 달러/원 환율 1,382~1,392원 전망] | G3137: 이민혁 | H3137: 1382 | I3137: 1392 | J3137: =IFERROR(AVERAGE(H3137:I3137),"") -> 1387 | K3137: =IFERROR(I3137-H3137,"") -> 10
A3138: 45876 | B3138: 45876 | C3138: 0.36805556 | D3138: UTC+9 | E3138: [달러/원 환율] 글로벌 약 달러 속, 반도체 관세 경계에 제한적 하락 예상 전일 달러/원 환율은 소폭 하락 개장한 이후 상승세로 전환. 오전 장중 중국 인민은행 절하 고시에 따른 위안화 약세에 연동한 가운데, 결제수요 유입 및 외국인의 국내주식 순매도에 1,390원 상회. 오후장에서는 고점 매도에 무거운 흐름 이어지며 혼조, 전일 종가 대비 1.2원 상승한 1,389.5원에 정규장 마감. 야간장에서는 연준 금리인하 기대에 따른 달러 약세에 하락하며 1,386.4원에 마감. 역외 NDF 환율은 4.70원 하락한 1,382.50원에 최종 호가 금일 달러/원 환율은 간밤 달러 약세와 역외 거래를 감안해 1,380원대 초중반에서 하락 개장 예상. 연준 인사들의 연이은 금리인하 시그널이 달러 약세 자극. 이에 따라 달러/원도 하방 우세, 달러 추가 약세 시 1,370원대 진입 시도. 다만 트럼프 대통령의 반도체 관세 100% 부과 발표가 원화 강세를 제약할 가능성. 금일 환율은 달러 약세 속, 반도체 관세 경계에 제한적 하락 예상 [글로벌 동향] 연준 인사들의 연이은 금리인하 시그널에 달러 약세 전환 전일 미 달러화는 연준 인사들의 완화적 발언 소화하며 약세 전환. 주요 6개국 통화로 구성된 달러화 지수는 0.54% 하락한 98.23pt 기록. 닐 카시카리 미니애폴리스 연은 총재는 관세가 인플레이션에 미치는 영향은 불확실한 반면, 경제는 둔화하고 있다고 진단. 그는 우선 금리를 인하하고 상황을 지켜보는 게 낫다고 언급. 리사 쿡 연준 이사, 수전 콜린스 보스턴 연은 총재는 급격한 고용 둔화에 대해 우려를 표명하며 금리인하 가능성을 시사. 메리 데일리 샌프란시스코 연은 총재는 고용 리스크로 인해 향후 몇 달 내 금리를 내려야 한다고 언급. 이 같은 연준 인사들의 완화적 발언에 9월 인하 확률은 95.5%, 연내 인하 폭 기대치는 60bp로 확대 (선물시장). 미 국채금리의 경우 2년물은 연준 인하 기대에 하락했으나, 10년물은 국채 입찰 부진에 상승. 뉴욕증시는 연준 인하 기대 등 위험선호심리에 3대 지수 상승 마감 [마켓 이슈] 차기 연준 의장 삼파전, 누가 되든 연준 금리인하 기대는 확산 최근 미국 고용지표의 쇼크와 함께 아드리아나 쿠글러 연준 이사의 사임까지 겹치며, 시장에서는 트럼프 대통령의 차기 연준 의장 지명에 대한 관심이 증대. 베팅 사이트가 예측하는 차기 연준 의장은 케빈 워시 전 연준 이사 (24.0%), 케빈 해싯 현 백악관 국가경제위원회 위원장 (27.8%), 그리고 크리스토퍼 월러 현 연준 이사 (12.1%) 등. 세 인사의 과거 발언을 미루어봤을 때, 금리인하에 가장 적극적인 인사는 케빈 해싯 위원장. 그는 연준 금리가 현재보다 3%p 더 낮아야 한다고 발언하는 등 인플레이션 억제보다는 성장 촉진에 집중하는 성향. 케빈 워시 전 이사는 금리인하 주장과 동시에 연준의 양적완화 (QE)에 비판적 입장이며 연준 개혁을 주장. 크리스토퍼 월러 이사는 고용 리스크를 경계하며 연준의 선제적 대응을 강조. 세 인사 모두 금리인하에 우호적 인사라는 점에서 누가 지명되든 연준 금리인하에 대한 기대는 더욱 커질 것으로 예상 | F3138: 이번 금리인하 사이클은 케빈과 함께 [금일 달러/원 환율 1,378~1,390원 전망] | G3138: 이민혁 | H3138: 1378 | I3138: 1390 | J3138: =IFERROR(AVERAGE(H3138:I3138),"") -> 1384 | K3138: =IFERROR(I3138-H3138,"") -> 12
A3139: 45877 | B3139: 45877 | C3139: 0.36805556 | D3139: UTC+9 | E3139: [달러/원 환율] 글로벌 약 달러에 하방 우세, 1,370원대 진입 시도 예상 전일 달러/원 환율은 연준 인사들의 금리인하 발언에 따른 달러 약세에 1,385원으로 개장한 이후 하락세 지속. 반도체 관세 경계에도 불구하고, 달러 약세와 함께 국내증시 호조 등 위험선호 분위기에 장중 1,380원 하회. 이후 저가 매수에 소폭 반등하며 전일 종가 대비 8.3원 하락한 1,381.2원에 정규장 마감. 야간장에서는 차기 연준 의장으로 크리스토퍼 월러 이사의 부상에 달러가 강세를 보이며 1,386.0원에 마감. 역외 NDF 환율은 2.15원 상승한 1,381.00원에 최종 호가 금일 달러/원 환율은 간밤 달러 약세와 역외 거래를 감안해 1,380원대 초중반에서 개장 예상. 미러 정상회담 개최 기대와 BOE 매파적 인하, 그리고 연준 이사 지명 등을 소화하며 달러 약세. 이에 따라 달러/원도 하방 우세, 장중 1,370원대 진입 시도 예상. 1,380원 하향 돌파 시, 다음 지지선은 50일 이동평균선 1,374원. 반면 결제 수요 및 저점 매수 시 전일 고점 1,388원까지는 반등 가능 [글로벌 동향] 연준 이사 지명에 달러 약세, 차기 의장 후보로 월러 부상 전일 미 달러화는 유로 및 파운드 절상과 함께 연준 이사 후임 지명에 약세 지속. 주요 6개국 통화로 구성된 달러화 지수는 0.15% 하락한 98.08pt 기록. 유로화는 트럼프푸틴 미러 정상회담 추진 소식에 강세. 정상회담 기대로 인해 하락한 국제유가도 달러 약세에 기여. 영국 파운드화는 영란은행 (BOE)의 매파적 인하에 강세. BOE는 25bp 인하를 결정했지만 의견은 서로 팽팽 (인하 5, 동결 4). 트럼프 대통령의 스티븐 미란 백악관 경제자문위원회 (CEA) 위원장 연준 이사 지명 소식에 달러 가치 급락. 트럼프 최측근인 미란 지명에 따른 연준 인하 기대 및 독립성 훼손 우려 등이 달러 약세 자극. 스티븐 미란은 내년 1월까지 한시적으로 이사직 수행 예정. 차기 연준 의장으로는 현 연준 이사인 크리스토퍼 월러가 부상. 일부 외신 보도에 따르면, 월러 이사는 의장직과 관련해 트럼프 측 인사와 만난 것으로 확인 [마켓 이슈] 고용 패턴으로 살펴본 경기침체 가능성, 연준의 '빅 컷'도 염두 최근 미국 고용지표 부진 속, 경기침체 진입 가능성에 주목. 특히 비농업 부문 신규 고용의 급감이 눈에 띄는데, 과거 통계 패턴상 현재 신규 고용자수가 과거 경기침체 진입 직전 수준과 유사하기 때문. 1980년 이후 총 6번의 경기침체 시기 중 코로나를 제외한 5번의 시기에서, 경기침체 진입 직전 몇 달 간 신규 고용은 어김없이 10만명 하회. 현재 신규 고용자수가 3개월 연속 10만명을 하회하고 있다는 점을 과거 패턴에 대입해보면, 근시일내 미국의 경기침체 진입 가능성도 배제할 수는 없는 상황. 9월 초 발표될 비농업 신규 고용이 또다시 10만명을 하회하거나 실업률이 큰 폭 상승할 경우, 연준의 9월 '빅 컷 (50bp)' 가능성도 열려있다는 판단. 이때 달러는 연준 인하 기대로 인한 약세 압력과 침체 우려에 따른 안전자산 선호 사이에서 변동성이 확대될 전망. 달러/원의 경우 외부 충격에 취약한 원화 특성상 더 큰 변동성을 보일 가능성 | F3139: 스케치 끝난 트럼프의 연준 구상 [금일 달러/원 환율 1,374~1,388원 전망] | G3139: 이민혁 | H3139: 1374 | I3139: 1388 | J3139: =IFERROR(AVERAGE(H3139:I3139),"") -> 1381 | K3139: =IFERROR(I3139-H3139,"") -> 14
A3140: 45880 | B3140: 45880 | C3140: 0.36805556 | D3140: UTC+9 | E3140: [달러/원 환율] 미 물가지표 경계 및 수급 주체 관망에 박스권 등락 예상 전일 달러/원 환율은 트럼프의 연준 이사 지명 이슈에 따른 달러 약세에 하락 개장한 이후 1,380원 일시 하회. 하지만 장초반부터 유입되는 결제 수요와 더불어 외국인의 국내주식 순매도 등에 상승세로 전환. 오후장에서는 달러 강세에 연동하며 1,390원 터치, 전일 종가 대비 8.4원 상승한 1,389.6원에 정규장 마감. 야간장에서는 특별한 이벤트는 없었던 가운데, 고점 매도에 소폭 하락하며 1,386.5원에 마감. 역외 NDF 환율은 0.70원 하락한 1,386.50원에 최종 호가 금일 달러/원 환율은 주말간 달러 강세 및 역외 거래를 감안해 1,380원대 후반에서 개장 예상. 금일은 주목할 만한 경제지표가 없는 가운데, 내일 밤 발표될 미국 CPI 경계하며 환율 방향성이 뚜렷하진 않을 전망. 1,390원 위에서는 수출 네고 및 고점 매도에 무거운 흐름. 1,380원대에서는 글로벌 달러 가치에 연동되며 하단 지지. 금일 환율은 역내외 수급 주체들의 관망으로 인해 개장가 중심으로 좁은 박스권 등락 예상 [글로벌 동향] 미 달러, 국채금리, 증시 상승. 차기 연준 의장 후보 확대 전일 미 달러화는 특별한 경제지표 발표는 없었던 가운데, 반발 매수 및 미 국채금리 상승에 연동해 강세 전환. 주요 6개국 통화로 구성된 달러화 지수는 0.19% 상승한 98.27pt 기록. 유로/달러 환율은 미국-러시아의 러-우 종전 합의 추진 소식에 장중 1.17달러부근까지 상승한 뒤 하락 조정. 파운드/달러는 지난주 영란은행 (BOE)의 매파적 인하 여파가 이어지며 소폭 상승. 일본 엔화 환율은 관세 불확실성 완화에도 정국 불안에 148엔 부근까지 상승. 한편 미국 국채금리는 금주 발표될 7월 물가지표 경계에 장단기물 대체로 상승. 뉴욕증시는 러-우 종전 기대 및 애플 반도체 관세 면제 소식에 3대 지수 모두 상승. 애플 주도 기술주 호조에 나스닥 지수는 사상 최고치 경신. 일부 외신에 따르면, 트럼프 대통령은 차기 연준 의장 후보를 10명까지 확대, 추가된 후보로는 제임스 불러드 전 연은 총재 등. 이에 차기 의장 관련 불확실성은 더욱 증대 [마켓 이슈] 연준 9월 금리인하에 쐐기를 박을 미국 7월 소비자물가 (CPI) 이번 주 화요일 (12일)에는 미국의 7월 소비자물가지수 (CPI)가 발표될 예정. 지난 7월 비농업 고용 충격으로 인해 연준 금리인하 재개에 대한 기대가 커진 상황 속에서 이번 CPI 결과에 따른 연준 금리 경로 기대 변화에 주목. 7월 CPI의 관건은 관세가 물가에 미친 영향, 그리고 주거비 등 서비스 부문의 물가상승 압력 둔화 여부. 관세 영향을 크게 받는 상품 물가가 근원 CPI에서 차지하는 비중은 23%에 불과. 반면에 주거비를 포함한 서비스 부문의 비중은 77%로 근원 CPI의 대부분을 차지 (주거비 비중 43%). 관세로 인해 근원 상품 부문의 인플레이션 압력은 한층 더 커질 것으로 보이나, 주거비를 중심으로 서비스 부문의 디스인플레이션이 관세 영향을 상당 부분 상쇄시킬 것으로 예상. 따라서 7월 CPI는 시장 예상보다 높지 않을 것으로 보이며, 이는 연준 9월 금리인하에 쐐기를 박을 것으로 판단 | F3140: CPI D-1, 역내외 플레이어 눈치게임 시작 [금일 달러/원 환율 1,385~1,393원 전망] | G3140: 이민혁 | H3140: 1385 | I3140: 1393 | J3140: =IFERROR(AVERAGE(H3140:I3140),"") -> 1389 | K3140: =IFERROR(I3140-H3140,"") -> 8
A3141: 45881 | B3141: 45881 | C3141: 0.36805556 | D3141: UTC+9 | E3141: [달러/원 환율] CPI 경계에 혼조, 미중 합의 등 위험선호에 제한적 하락 전일 달러/원 환율은 미국 물가지표에 대한 경계가 이어지는 가운데, 장중 미 달러화 약세 및 중국 위안화 강세에 연동하며 1,385원까지 하락. 이후 경계 심리로 인해 추가 하락은 제한되며 1,380원대 후반에서 등락. 오후장에서는 뚜렷한 방향성 없이 혼조세 보이다가 전일 종가 대비 1.6원 하락한 1,388.0원에 정규장 마감. 야간장에서는 미국 7월 소비자물가지수 경계에 따른 달러 강세에 소폭 상승하며 1,390.5원에 마감. 역외 NDF 환율은 2.65원 상승한 1,388.15원에 최종 호가 금일 달러/원 환율은 간밤 달러 강세와 역외 거래를 감안해 1,390원 부근에서 보합권 개장 예상. 금일 21:30 발표될 미 CPI에 대한 경계에 달러 혼조, 이에 환율도 뚜렷한 방향성 없이 등락할 전망. 다만 미중 관세 유예 합의에 따른 위험선호심리가 원화에 힘을 실어줄지가 관건. 금일 환율은 보합권 개장 이후 미 CPI 경계에 방향성은 부재할 전망이나, 국내증시 호조나 중국 위안화 강세 시 제한적 하락 시도 예상 [글로벌 동향] 미 CPI 경계에 달러 강세, 미중은 90일 관세 유예 합의 전일 미 달러화는 러우 휴전 불확실성과 미국 물가지표 경계에 강세 시현. 주요 6개국 통화로 구성된 달러화 지수는 0.25% 상승한 98.51pt 기록. 15일 미러 정상회담을 앞두고 주요국 관계자들은 러시아에 강경한 발언. 유럽연합 (EU)의 외교안보 관계자는 러시아가 무조건적인 휴전에 동의해야 한다고 언급. 젤렌스키 우크라이나 대통령은 러시아가 어떤 보상도 받아서는 안된다고 발언. 이 같은 강경 발언에 러우 휴전 합의 불발 가능성이 커지며 유로화는 약세. 금일 21:30에 발표될 미국 7월 소비자물가지수 (CPI)에 대한 경계는 미 국채금리 상승에 기여. 컨센서스에 따르면, 7월 근원 CPI는 전월대비 0.3%, 전년대비 3.0% 상승으로 전월치 (+0.2%, +2.9%)보다 상승 폭 확대 예상. 한편 트럼프 대통령은 미중 관세를 90일 추가 유예하는 행정명령에 서명. 지난 5월 미중 양국의 115%p 관세율 인하 조치는 이번 행정명령으로 11월 9일까지 연장 [마켓 이슈] 하반기부터 달라질 수 있는 외환 수급 여건, 달러/원에 노이즈 올해 우리나라의 외환 수급 여건은 5월 처음으로 순유입 전환된 이후 6월에도 순유입 기조가 이어진 것으로 확인. 외환 공급의 상당 부분은 수출과 수입의 차이인 경상수지 흑자에서 비롯 (6월 142.7억 달러). 하지만 동 기간 직접투자 및 증권투자 부문에서 각각 31.8억 달러, 44.4억 달러의 외환 순유출이 발생하며, 5월 대비 순유입 규모가 감소 (5월 90.2억 달러 → 6월 66.5억 달러). 지난 7월 수출 호조와 외국인의 국장 유입을 고려하면 7월 수급 여건도 순유입 기조 유지가 예상 (8/6일 FX 시황 자료). 하지만 8월 상호관세 발효에 따른 수출 둔화, 국내 투자자의 지속적인 해외투자 수요, 그리고 미국이 한국에 요구한 3,500억 달러 규모 대미 투자 등을 감안하면, 향후 외환 순유입 규모는 더욱 줄어들거나 순유출로 전환할 가능성. 이는 앞으로 글로벌 달러가 약세인 상황에서도 달러/원의 하단을 지지하는, 일종의 수급 노이즈로 작용할 소지 | F3141: CPI D-day, 21:30까지 숨 참고 대기 [금일 달러/원 환율 1,386~1,394원 전망] | G3141: 이민혁 | H3141: 1386 | I3141: 1394 | J3141: =IFERROR(AVERAGE(H3141:I3141),"") -> 1390 | K3141: =IFERROR(I3141-H3141,"") -> 8
A3142: 45882 | B3142: 45882 | C3142: 0.36805556 | D3142: UTC+9 | E3142: [달러/원 환율] 달러 약세에 하락 개장, 장중 1,370원대 진입 시도 예상 전일 달러/원 환율은 달러 강세 영향에 1,391원으로 소폭 상승 개장. 이후 미중 관세 유예 연장에 따른 위험선호와 중국 위안화 강세에 연동해 1,387원까지 하락하기도 했으나, 당일 저녁에 발표될 미국 CPI 경계에 추가 하락은 제한적. 오후장에서는 3원 이내 매우 좁은 박스권 등락하다가 전일 종가 대비 1.9원 상승한 1,389.9원에 정규장 마감. 야간장에서는 CPI 발표 이후 연준 금리인하 기대에 따른 달러 약세에 하락하며 1,384.4원에 마감. 역외 NDF 환율은 5.75원 하락한 1,381.80원에 최종 호가 금일 달러/원 환율은 간밤 달러 약세와 역외 거래를 감안해 1,380원대 초중반으로 하락 개장 예상. 미 CPI가 예상에 부합했고 관세 영향도 미미해 연준 9월 인하 기대는 더욱 확산. 이에 따른 달러 약세가 달러/원 하락을 주도할 전망이며, 장중 달러 약세 심화 시 1,370원대 진입 시도. 다만 1,380원대에서 유입되는 결제 수요, 그리고 미 증시 회복 기대에 따른 내국인의 해외투자 수요 (달러 수요)가 하단 지지 [글로벌 동향] 관세 영향 미미했던 7월 CPI, 더 확실해진 연준 9월 인하 전일 미 달러화는 대체로 예상에 부합한 미국 CPI와 트럼프의 파월 소송 검토 소식에 약세. 주요 6개국 통화로 구성된 달러화 지수는 0.45% 하락한 98.06pt 기록. 미국의 7월 소비자물가지수 (CPI)는 전월비 0.2% 상승하며 예상치 부합, 전년비로는 2.7% 상승해 예상치 (+2.8%) 소폭 하회. 7월 CPI 상승의 대부분은 주거비 및 메디케어 등 서비스 부문이 주도. 주거비 제외 근원 CPI (슈퍼 코어)는 전월비 0.5% 상승하며 1월 이후 최고치. 반면 관세에 민감한 근원 상품 물가는 0.2% 상승에 그치며 전월과 유사. 전월 관세 영향이 반영됐던 품목 (가정용 가구 및 용품, 장난감, 비디오 및 오디오 제품 등)의 가격 상승 폭이 7월에는 축소. 7월 CPI 발표 이후 연준의 9월 금리인하 기대는 더욱 강화 (FedWatch 금리인하 확률 93.4%). 한편 트럼프 대통령은 연준 건물 보수 공사 문제를 지적하며 파월 의장 소송을 검토 중이라 밝힘 [마켓 이슈] 관세의 물가 영향은 일시적, 연준은 고용 리스크에 더욱 초점 최근 전미경제연구소 (NBER) 연구에 따르면, 영구적 관세 충격 (permanent tariff shocks)은 인플레이션에 '일시적인 충격 (one time inflation spike)' 만을 야기할 것으로 추정. 관세율이 10%p 상승하면 향후 6개월간 물가상승률이 약 1%p 상승한 뒤, 중장기적으로는 그 영향이 소멸된다는 분석. 이를 트럼프 행정부의 관세 부과 시점 (올해 4~8월)에 대입하면, 관세의 인플레이션 영향은 빠르면 올해 4분기, 늦어도 내년 1분기부터 사라질 가능성. 관세의 물가 영향이 일시적이라면, 향후 연준은 물가보다는 고용 리스크에 초점을 맞춰 통화정책을 운용해 나갈 가능성이 높다는 판단. 즉 앞으로 발표될 물가지표에서 관세 영향이 일부 확인되며 인플레이션 우려가 부각될 수 있으나, 최근의 고용 쇼크를 감안하면 연준의 9월 금리인하는 여전히 유력. 만약 8월 고용마저 크게 둔화될 경우, 9월 빅 컷은 물론 연내 3회 금리인하 가능성도 열려 있다는 생각 | F3142: 소문난 CPI에 관세는 없었다 [금일 달러/원 환율 1,378~1,387원 전망] | G3142: 이민혁 | H3142: 1378 | I3142: 1387 | J3142: =IFERROR(AVERAGE(H3142:I3142),"") -> 1382.5 | K3142: =IFERROR(I3142-H3142,"") -> 9
A3143: 45883 | B3143: 45883 | C3143: 0.36805556 | D3143: UTC+9 | E3143: [달러/원 환율] 역외 플레이어 중심으로 달러 매도세, 1,370원대 안착 전일 달러/원 환율은 예상에 부합한 미국 7월 CPI와 이에 따른 연준 금리인하 기대에 달러가 약세를 보이며 하락 개장. 장중 저가 매수에 1,386원까지 반등하기도 했으나, 국내증시 호조와 외국인 자금 순유입 등 위험선호에 1,380원대 초반에서 등락. 전일 종가 대비 8.2원 하락한 1,381.7원에 정규장 마감. 야간장에서는 연준 금리인하 기대 및 달러 약세 지속으로 인해 추가로 하락하며 1,379.4원에 마감. 역외 NDF 환율은 1.85원 하락한 1,377.50원에 최종 호가 금일 달러/원 환율은 간밤 달러 약세와 역외 거래를 감안해 1,380원 부근 하락 개장 예상. 미국 고용 부진과 물가 안정으로 연준의 9월 빅 컷 기대 부상. 이에 따른 달러 약세가 달러/원 하방에 기여, 장중 80원 하회 이후 70원대 안착 시도. 연휴 앞두고 역내 거래는 한산한 가운데, 역외 플레이어 중심으로 달러 매도세가 출회하며 환율 하방 우세. 금일 환율은 약 달러 추종하며 50일 이동평균선 1,375원까지 하락 가능 [글로벌 동향] 연준 9월 빅 컷 부상에 달러 약세, 유로/달러 1.17선 돌파 전일 미 달러화는 연준 9월 빅 컷 기대 반영하며 약세 지속. 주요 6개국 통화로 구성된 달러화 지수는 0.27% 하락한 97.79pt 기록. 금주 미국의 7월 소비자물가지수 (CPI) 발표 이후 현재 FedWatch의 연준 9월 금리인하 확률은 100% (25bp 인하 95.8%, 50bp 인하 4.2%). 트럼프 행정부의 연이은 연준 인하 압박도 9월 빅 컷 기대 형성에 기여. 트럼프 대통령은 금리가 지금보다 3~4%p 낮아야 한다고 언급. 베센트 장관은 9월 50bp를 시작으로 앞으로 금리를 150~175bp 낮춰야 한다고 발언. 연준 인하 기대에 미 국채금리는 장단기물 모두 하락. 벤치마크인 미 10년물 국채금리는 5.5bp 하락 (4.236%). 뉴욕증시 역시 연준 인하에 따른 부양 기대감에 3대 지수 모두 상승 마감. 유로화는 15일 미러 정상회담에서 러우 휴전 논의 기대에 강세. 유로/달러는 7월 말 이후 처음으로 1.17달러선 상회 [마켓 이슈] 다시 기본으로 돌아가서... 환율은 결국 경제 펀더멘털의 차이 기본적으로 환율은 양국 경제의 펀더멘털 차이, 구체적으로는 양국의 실질 경제성장률 차이에 의해 결정. 또한 시장 가격 특성상, 환율은 미래의 경제성장률, 즉 양국 성장률 기대치 차이를 반영. 이를 달러/원 환율에 적용해 보면, 미국 성장 기대치가 한국 성장 기대치보다 높으면 환율 상승, 그 반대이면 환율 하락으로 이해. 올해 달러/원과 양국 성장 기대치 간의 관계를 살펴보면, 2분기 무렵 미국 2026년 성장 기대치가 상호관세 우려로 큰 폭 하락하면서 환율도 동반 하락. 하지만 6월부터 미국 성장 기대치는 상승 전환한 반면, 한국 성장 기대치는 관세 영향 및 건설경기 부진 우려에 하락하며 환율도 상승 전환. 즉 향후 달러/원 방향을 결정할 핵심 변수로, 미국 고용 부진 여파에 따른 성장 기대치 하락, 그리고 한국 반도체 수출 호조 지속 및 건설경기 회복 여부에 주목. 양국 성장 기대차 축소 시 (KR > US), 달러/원 환율 레벨은 더욱 낮아질 것으로 전망 | F3143: 작년 9월이 생각나는 요즘 (feat. Big Cut) [금일 달러/원 환율 1,375~1,385원 전망] | G3143: 이민혁 | H3143: 1375 | I3143: 1385 | J3143: =IFERROR(AVERAGE(H3143:I3143),"") -> 1380 | K3143: =IFERROR(I3143-H3143,"") -> 10
A3144: 45887 | B3144: 45887 | C3144: 0.36805556 | D3144: UTC+9 | E3144: [달러/원 환율] 하락 개장 이후 글로벌 달러 약세 추종하며 상승분 반납 전일 달러/원 환율은 연준 금리인하 기대에 따른 달러 약세에 1,378원으로 하락 개장 이후 상승세로 전환. 장중 지속적인 달러 약세에도 불구하고 역내 결제 수요 및 저가 매수가 하단을 지지, 외국인의 국내주식 매도세까지 겹치며 장중 1,385원 터치. 이후 고점 매도에 소폭 조정되며 전일 종가 대비 0.3원 상승한 1,382.0원에 정규장 마감. 야간장에서는 미국 7월 생산자물가 시장 예상 상회에 따른 달러 강세에 1,389.5원에 마감. 역외 NDF 환율은 7.05원 상승한 1,386.70원에 최종 호가 금일 달러/원 환율은 연휴간 달러 약세에도 역외 거래를 감안해 1,380원대 후반에서 상승 개장 예상. 결제수요 및 해외투자 위한 달러 환전 등 역내 수급 요인이 환율 하단 지지. 하지만 미국 소비심리 약화 및 러우 협상 기대에 따른 달러 약세가 달러/원에 지속적인 하락 압력. 금일 환율은 상승 개장 이후 고점 매도에 상승분 반납할 것으로 예상. 글로벌 약 달러에 따른 역외 달러 매도세에 1,380원대 초반까지 하락 가능 [글로벌 동향] 일본 GDP 서프라이즈, 미국 소비심리 약화에 달러 약세 전일 미 달러화는 주요국 경제지표 결과를 소화하는 가운데, 미러 정상회담 기대에 약세 시현. 주요 6개국 통화로 구성된 달러화 지수는 0.37% 하락한 97.84pt 기록. 금요일 발표된 일본 2분기 실질GDP는 전기비 연율 1.0% 증가하며 예상치 (+0.4%) 및 전월치 (-0.2%) 모두 큰 폭 상회. 이에 일본 엔화는 달러 대비 0.38% 절상되며 147엔 부근까지 하락. 미국 7월 소매판매는 전월비 0.5% 증가하며 예상치 (+0.6%) 하회했으나, 관리 그룹 소매판매는 0.5% 증가하며 예상치 (+0.4%) 상회. 미시간대의 8월 소비자신뢰지수는 58.6pt를 기록하며 예상치 (62.0pt) 및 전월치 (61.7pt) 모두 하회. 하지만 1년 및 5~10년 기대 인플레이션은 전월대비 각각 0.4%p 및 0.5%p 상승하며 물가 우려 반영. 유로화는 미러 정상회담에서 러우 휴전 논의 기대에 강세. 트럼프 대통령은 회담 이후 기자회견에서 추후 합의 가능성이 매우 높다고 발언 [마켓 이슈] 연준이 금리 내리면 달러는 약해질까? 작년 하반기 사례 재점검 최근 미국 고용 부진과 관세의 제한적 물가 영향이 확인되며, 시장에서는 연준의 9월 금리인하 기대가 부상. 이에 따라 달러가 약세 흐름을 이어갈 것이란 전망도 힘을 얻고 있음. 하지만 지난해 연준의 9월 금리인하 시작 이후 올해 초까지 달러 추이를 보면, 달러는 오히려 강세를 보인 전적. 지난해 9월 당시 연준은 미국 경제가 침체 국면이 아님에도 불구하고, 선제적 대응 측면에서 보험성 금리인하를 단행. 9월 빅 컷 이후 24년말까지 50bp 추가 인하. 동 기간 미국의 25년 연간 성장률 기대치는 1.7%에서 2.1%로 상승했고, 25년말 연준 금리 기대치는 2.9%에서 3.9%로 상승. 즉 연준의 선제적 대응이 경기 부양 기대로 이어지며 달러 강세를 자극한 것으로 판단 (트럼프 트레이드 영향도 일부 작용). 즉, 이번 9월 FOMC에서 만약 빅 컷을 하더라도 고용 및 소비 등 실물경기의 회복 조짐이 나타난다면, 달러가 강세로 전환될 리스크도 염두 | F3144: 연준 금리와 달러, 우리 무슨 사이야? [금일 달러/원 환율 1,380~1,391원 전망] | G3144: 이민혁 | H3144: 1380 | I3144: 1391 | J3144: =IFERROR(AVERAGE(H3144:I3144),"") -> 1385.5 | K3144: =IFERROR(I3144-H3144,"") -> 11
A3145: 45888 | B3145: 45888 | C3145: 0.36805556 | D3145: UTC+9 | E3145: [달러/원 환율] 미국 품목 관세 부과와 러-우 종전 기대 등 재료 혼조 전일 달러/원 환율은 미국의 물가 상승 등 인플레이션 재개 우려에 1,390원까지 상승했으나, 역외 달러 조정에 상승 폭을 축소, 종가는 3.0원 상승한 1,385.0원에 장중 마감함. 야간장에서는 미 달러화의 강세와 뉴욕증시 조정, 위험선호 약화 등에 상승 폭이 확대, 1,388.1원을 기록함. NDF 역외 환율 역시 달러 강세와 비달러 통화 약세, 미국 물가 경계 등에 3.85원 상승한 1,386.3원에 호가됨 금일 달러/원 환율은 전일 미 달러화 강세와 역외환율 상승 등을 감안하여 전일과 유사한 1,380원대에서 등락할 것으로 예상됨. 미 트럼프 정부는 철강, 알루미늄 및 파생상품에 대해서도 50%의 고율 관세를 부과할 것이라고 밝힘. 이는 국내 철강 및 관련 제품 (변압기 등)에도 대미 수출에 부정적. 한편, 미, 러, 우 등 3자 회담 개최와 러우 종전에 대한 가능성도 있어 지정학적 불안 완화는 긍정적. 달러/원은 악재와 호재가 혼조하고 금리, 주식 등의 박스권 등락에 1,380원대에서 정체될 전망 [글로벌 동향] 미국 물가 상승 경계와 미러 정상회담 불발 등에 달러 강세 전일 미 달러화는 미국 경제지표 부진에도 지난주 발표되었던 생산자물가 등 물가 지표 상승에 대한 경계와 미러 정상회담 불발에 따른 지정학적 불안 등에 강세를 보임. 달러화 지수는 0.34% 상승한 반면 유로/달러는 0.40% 하락, 일본 달러/엔 환율도 0.45% 상승함. 전일 발표된 미국 뉴욕 연준의 서비스업 경기활동 지수는 11.7 하락하여 전월 9.3 하락보다 하락 폭이 컸으며, 8월 전미주택협회 (NAH) 지수는 32로 예상치 34를 하회함. 그럼에도 물가 상승에 대한 경계와 9월 연준의 금리인하 기대 약화 등에 미국 단기와 장기 금리가 소폭 상승했고, 뉴욕증시는 조정을 보이며 위험 선호 심리는 다소 약화됨. 트럼프 대통령은 젤렌스키와 백악관 회담을 통해 미, 러, 우 등 3자 회담을 통해 러-우 종전에 나설 것이라고 밝힘. 그럼에도 영토 문제 등에 러-우 종전에 대한 기대가 강하지 않아 유로화, 영국 파운드화 등이 약세를 보임 [마켓 이슈] 미국 물가에 대한 엇갈린 결과, 연준의 9월 금리인하 기대 낮춰 지난주 발표된 미국의 소비자물가 및 생산자물가, 수입물가, 그리고 미시건대 기대 인플레이션율 결과가 다소 상이한 것으로 발표되어 물가에 대한 판단이 어려워졌음. 미국 7월 소비자물가는 예상치에 부합한 전월비 0.2~0.3%로 발표되어 관세 영향이 미미한 것으로 평가됨. 하지만 7월 생산자물가는 전월비 0.9% 상승, 수입물가도 0.4% 상승하여 소비자물가보다 더 큰 폭의 물가상승률을 기록, 주 후반 발표된 8월 미시건대 기대 인플레이션 1년도 4.5%에서 4.9%로 반등함. 다만, 그 이전 발표된 뉴욕 연은의 7월 조사에서 기대 인플레이션 단기는 3.09%에 불과함. 물가에 대한 결과가 엇갈린 배경은 관세가 기업의 생산 물가를 상승시키고, 이 물가 압력이 아직 소비자에게 전가되지 않은 것으로 해석됨. 고용 부진에도 물가에 대한 경계가 남아 있어 9월 연준의 금리인하 기대는 소폭 하락, 전년도의 빅 컷 가능성은 희박해졌음 | F3145: 방향성을 잃어 버린 금융시장과 달러/원 환율 [금일 달러/원 환율 1,382~1,391원 전망] | G3145: 문정희 | H3145: 1382 | I3145: 1391 | J3145: =IFERROR(AVERAGE(H3145:I3145),"") -> 1386.5 | K3145: =IFERROR(I3145-H3145,"") -> 9
A3146: 45889 | B3146: 45889 | C3146: 0.36805556 | D3146: UTC+9 | E3146: [달러/원 환율] 국내외 투자심리 혼조 속에 환율 상단만 조금씩 상승 중 전일 달러/원 환율은 미 달러화 강세를 반영하여 3.5원 상승 출발한 가운데 러-우 전쟁에 대한 기대감이 약화되고, 미국의 물가상승에 대한 경계심리 지속, 외국인의 국내 증시 및 국채 선물 매도 등 원화 회피에 종가는 5.9원 상승한 1,390.9원에 정규장 마감함. 야간장에서는 러우 종전 기대 약화와 유로화 약세, 달러 강세 영향에 1,390.9원까지 상승함. NDF 역외 환율도 2.35원 상승한 1,390.8원에 호가됨 금일 달러/원 환율은 미 달러화 강세와 나스닥 지수 조정, 위험회피 양상 등을 반영하여 1,390원대에서 등락할 것으로 예상됨. 국내 국고채 금리는 미국 국채 금리와 동조화를 보이고, 국내 증시 역시 나스닥지수에 연동함. 금리와 증시가 방향성을 잃고 혼조세를 보임에 따라 달러/원 환율도 달러 강세를 반영, 하단이 계속 상향되고 있음. 금주에는 러-우 협상과 잭슨홀 미팅 등 연준의 시간이라는 점에서 환율 역시 좁은 박스권 내에서 등락을 이어갈 것으로 예상됨 [글로벌 동향] 러우 종전 가능성 약화와 잭슨홀 미팅 앞두고 달러 강보합 전일 미 달러화는 주요 통화 대비 소폭 강세를 이어감. 미국 중재에도 러시아와 우크라이나의 종전 여부가 불투명한 가운데 7월 주택시장 지표는 혼조를 보였고, 국제 신용평가사인 S&P에서 미국 국채 등급을 A+ (안정적)로 유지했다는 소식에 강세를 이어감. 트럼프 대통령은 러시아의 푸틴 대통령이 협상을 원하지 않을 수도 있다고 발언하며, 러우 종전 가능성이 약화됨. 한편 미국 7월 주택착공건수는 전월보다 5.2% 증가했으나, 건축허가건수는 2.8% 감소하며 혼조를 보임. 또한, 오는 21일 새벽에는 7월 FOMC 의사록이 공개될 예정이며, 22일 잭슨홀 심포지움에서는 제롬 파월 연준 의장의 연설이 예정되어 있음. 전일 뉴욕증시는 다우산업지수가 상승했으나, S&P 지수와 기술주의 나스닥지수가 하락했는데, 특히 나스닥지수는 AI 거품론 등으로 주요 종목이 급락하며 시장의 위험회피심리를 자극함 [마켓 이슈] 국내 호재 부족에 외국인 투자 약화, 달러/원도 1,400원 근접 최근 국내 금융시장에 투자하는 외국인 자금이 감소하고 있음. 8월 들어 미국 고용 부진으로 연준의 금리인하 전망 등에 달러 약세를 기대, 외국인 투자가 유입되었으나, 지난주 발표된 미국 물가지표가 예상치를 상회하는 등 물가상승 경계감이 고조됨에 따라 외국인의 국내 증시에서 순매도와 국채 선물 매도 등이 계속되고 있음. 이는 원화 자산에 대한 회피로 볼 수 있으며, 달러/원 환율의 1,380원 하방을 제약하는 요인으로 판단됨. 대외 불확실성에도 국내 내부적으로 호재가 부족하다는 점도 문제, 국내 증시는 새 정부 출범 이후 단기 급등함에 따라 조정을 보이고 있는 가운데, 채권금리는 한국은행의 금리인하 기대 차단 등에 혼조세를 이어감. 3분기에는 소비 쿠폰 등으로 소비 진작이 예상되나, 건설 및 설비투자 부진, 트럼프의 반도체 관세 부과 예고 등으로 원화에 대한 투자심리가 회복되지 못하고 있음 | F3146: 시장의 재료 부재에 상단만 높아지는 환율 [금일 달러/원 환율 1,386~1,395원 전망] | G3146: 문정희 | H3146: 1386 | I3146: 1395 | J3146: =IFERROR(AVERAGE(H3146:I3146),"") -> 1390.5 | K3146: =IFERROR(I3146-H3146,"") -> 9
... A3234: 46021 | B3234: 46021 | C3234: 0.36805556 | D3234: UTC+9 | E3234: [달러/원 환율] 2025년 마지막 거래일, 종가는 1,420원대 마감 예상 전일 달러/원 환율은 0.3원 하락한 1,440원으로 출발했으나, 이후 국내 증시 상승 등 증시 호조와 외국인 주식 순매수 지속, 당국 물량으로 추정되는 달러 매도 압력, 수출 네고 물량까지 출회되어 종가는 10.5원 하락한 1,429.8원에 정규장이 마감됨. 야간장에서는 단기 급락에 대한 되돌림과 뉴욕증시 조정에 따른 위험회피 심리 등에 1,434.1원으로 반등, NDF 역외 환율도 1,430원대 초반에서 호가됨 금일 달러/원 환율은 올해 마지막 환율로 역외에서는 1,430원대까지 반등했으나, 전일에도 개장 이후 하방 압력이 지속되었다는 점, 연말 종가가 매우 중요하다는 점에서 다시 1,420원대로 회귀할 전망. 연말에 거래가 많지 않다는 점과 수출 업체의 네고물량 출회, 대외적으로 일본 엔화 및 중국 위안화 등 아시아 통화 강세, 마지막으로 정부의 환율 안정 의지 등 전일과 유사한 개장 이후 환율 하방이 예상됨 [글로벌 동향] 달러 강보합에도 일본 엔화와 중국 위안화의 동반 강세 전일 미 달러화는 연말로 시장 분위기가 차분한 가운데 일본 엔화의 강세에도 유로화 약세 등에 0.02% 상승, 강보합을 기록함. 경제지표가 부재한 가운데 미국 11월 잠정 주택판매는 전월대비 3.3% 증가하여 호조를 보였지만 댈러스 연준 제조업 활동지수는 - 10.9로 기준치를 하회하는 위축국면을 지속하여 상반된 결과로 발표됨. 전일 공개된 일본 BOJ 12월 금정위 의사록에서 일부 위원들이 너무 낮은 실질금리와 엔화의 과도한 약세를 지적하며 추가 금리인상 필요성을 강조함. 이에 달러/엔 환율이 0.27% 하락하여 엔화가 달러 대비 강세를 이어감. 중국 역외 위안화 환율은 다시 7.0위안을 하회했으며 지난 9월 이후 최저치를 기록함. 미국 국채 금리는 장단기에서 모두 소폭 하락했고, 뉴욕증시는 3대 지수 모두 조정을 보였으며, 국제유가는 2% 이상 상승함. 시장은 연말 거래가 많지 않은 가운데 조용하게 지나가고 있음 [마켓 이슈] 2025년 연말 종가, 여전히 원화는 주요 통화 대비 약세 달러/원 환율이 연말 앞두고 1주일 동안 약 40원 이상 하락했으나, 아직도 원화는 달러 대비 약세를 보이고 있음. 달러화 지수는 연초 107.8pt에서 전일 98pt로 연초 대비 9.1% 하락, 연평균으로는 3.2% 하락함. 반면 달러/원 환율은 연초 1,470원에서 전일 1,430원으로 2.7% 하락했으나, 연평균 환율은 1,422원으로 전년도 평균 환율 1,364원에 비해 4.2% 상승함. 즉 달러화는 전세계적으로 3% 이상 하락한 반면 달러/원 환율이 4.2% 상승했다는 점에서 원화는 달러 대비 약 7% 이상 약세를 보였음. 특히 지난 8월부터 원화의 달러 약세 양상은 심화, 10월부터 12월까지도 이러한 현상은 지속됨. 달러 약세에도 달러/원 환율 상승 배경으로 달러 부족현상을 지목하고 있으나 역내 달러 부족 현상보다 수요가 몰리는 가운데 공급이 부족한 수급 불균형 영향이 컸음. 따라서 2025년 환율 상승은 외환 수급 불균형이라고 판단됨 | F3234: 2025년 종가, 정부의 강한 환율 안정 의지 [금일 달러/원 환율 1,425~1,436원 전망] | G3234: 문정희 | H3234: 1425 | I3234: 1436 | J3234: =IFERROR(AVERAGE(H3234:I3234),"") -> 1430.5 | K3234: =IFERROR(I3234-H3234,"") -> 11
A3235: 46022 | B3235: 46022 | C3235: 0.36805556 | D3235: UTC+9 | E3235: [달러/원 환율] 연말 종가는 1,439원, 연평균은 1,422원으로 역대 최고 전일 달러/원 환율은 달러 강세 영향에 소폭 상승 개장한 이후, 꾸준한 결제수요 유입 등에 완만한 상방 흐름. 국내증시에서 외국인의 주식 순매도까지 가세하는 등 달러 수요 증가에 1,440원 근접. 이후 외환당국 종가관리 경계에 상단 제약되며 전일 종가 대비 9.2원 하락한 1,439.0원에 정규장 마감. 야간장에서는 정규장 마감 이후 저가 매수에 1,440원 상회한 이후 추가 상승한 뒤, 되돌림 나타나며 1,439.5원으로 마감. 역외 NDF 환율은 0.35원 하락한 1,437.10원에 최종 호가 금일 서울 외환시장은 연말연초를 맞아 휴장. 2025년 환율 종가는 1,439원 기록하며 지난해 종가인 1,472원 대비 33.5원 하락. 외환당국의 강한 개입과 국민연금 환헤지 재개가 연말 환율 하락에 기여. 하지만 연평균 환율은 1,422원으로 연간 기준 역대 최대치 기록. 역내 달러 수요 우위 등 수급 불균형이 금년 환율 상승의 주 요인. 내년 역시 구조적 수급 변화에 1,400원대 고환율 구간 유지 예상 [글로벌 동향] 별 내용 없던 FOMC 의사록, 미 달러화는 기술적인 강세 전일 미 달러화는 연말 맞아 거래량 한산한 가운데, 반발 매수 등 기술적 요인에 강세. 주요 6개국 통화로 구성된 달러화 지수는 0.22% 상승한 98.25pt 기록. 시장은 주요 경제지표 부재 속, FOMC 의사록에 주목. 하지만 이미 예상된 내용이었다는 점에서 시장 반응은 미온적. 의사록에 따르면, 대부분 위원들은 인플레이션 완화 시 추가 인하가 적절하다는 입장. 다만 일부 위원들은 당분간 금리동결 기조 유지를 주장. 시장 참가자들은 내년 3월부터 연준이 금리인하를 재개할 것으로 기대. FedWatch에서 1월 금리인하 확률은 14.9%, 3월 확률은 53.1%로 반영 중. 미 국채금리는 의사록 재료 소화하며 장단기물 혼조 마감. 한편 시카고 PMI는 전월대비 7.2p 급등한 43.5p 기록. 하지만 기준치인 50p는 하회하며 업황 위축 국면 시사. 중국 역외 위안화 환율은 달러당 7위안 하회하며 지난해 9월 이후 최저치 기록 [마켓 이슈] 고점은 낮아졌지만 높아진 눈높이... 1,400원대 머무를 달러/원 2025년 달러/원 환율은 1,439원으로 정규장 마감. 최근 1,480원을 넘나들던 국면과 비교하면 상당 폭 하락. 하지만 절대 수준으로는 여전히 과거 대비 높은 구간. 연평균 환율은 1,422원으로 역대 최고, 연말 기준으로는 1997년과 2024년 이후 세 번째로 높은 레벨. 단기적으로는 추가 하락 여력이 존재. 기술적으로 급격한 고점 형성 이후 조정 국면에 진입한 데다, 당국의 환율 안정 조치가 상단 제약 중. 대외적으로도 연준 금리인하 사이클, QT 종료, 차기 연준 의장 지명 등 달러 약세 환경이 조성 중. 다만 이를 원화의 추세적 강세로 해석하기에는 시기상조. 한미 금리 역전이 지속되고 있고, 거주자 해외투자 확대 등 구조적 달러 수요가 잔존. 이 같은 구조의 근원에는 한미 간 잠재성장률 역전이 자리 잡고 있음. 중장기 성장 기대의 상대적 우위가 미국에 있는 한, 달러/원 역시 과거 평균으로의 회귀보다는 1,400원대에 고착될 가능성이 크다는 판단 | F3235: 2025년 결산, 확연히 높아진 달러/원 눈높이 | G3235: 이민혁 | J3235: 1430.5
A3236: 46024 | B3236: 46024 | C3236: 0.36805556 | D3236: UTC+9 | E3236: [달러/원 환율] 새해 첫 개장, 역내 수급 대치에 1,440원 부근 박스권 2025년 12월 31일과 2026년 1월 1일 달러/원 환율은 서울 외환시장 휴장으로 거래 제한. 하지만 역외에서는 저가 매수세가 유입되며 하단 지지. 글로벌 달러가 소폭 약세를 보였고, 중국 위안화가 강세를 보였음에도 오히려 원화는 일본 엔화 약세에 일부 동조되는 모습. 하지만 연말 적은 거래량 속, 역외 달러/원 환율은 12월 30일 종가인 1,439원에서 큰 이탈 없이 보합권 등락. 역외 NDF 환율은 2.00원 상승한 1,439.45원에 최종 호가 금일 달러/원 환율은 주말간 엔화 약세와 역외 거래 감안해 1,440원 부근 개장 예상. 특별한 이벤트 없이 저가 매수세 유입되며 일시 반등 국면. 새해 맞아 거래량 부진한 가운데, 주로 역내 실수요에 따라 등락 예상. 거주자 해외투자용 달러 환전, 수입업체 결제수요 등이 하단 지지. 반면 국민연금 전략적 환헤지를 필두로 한 달러 매도 물량 출회 기대. 금일 환율은 한산한 거래 속, 역내 수급 대치에 박스권 등락 예상 [글로벌 동향] 미 달러화 약 보합, 위안화는 2024년 9월 이후 최대 강세 2024년 12월 31일 미 달러화는 연말 글로벌 주요 금융시장 휴장인 관계로 큰 변동 없이 약 보합. 주요 6개국 통화로 구성된 달러화 지수는 0.02% 하락한 98.24pt 기록. 31일 발표된 미국 고용지표는 시장 예상보다 다소 양호한 결과보였으나 시장 반응은 미온적. 신규 실업수당 청구건수는 19.9만건으로 집계되며 예상치 (21.8만건) 및 전주치 (21.5만건) 하회. 하지만 변동성이 비교적 적은 연속 실업수당 청구건수는 186.6만건으로 집계되며 예상치 (190.2만건) 및 전주치 (191.3만건) 하회. 중국의 역외 위안화는 중국 경제지표 호조에 강세 흐름 지속. 달러당 역외 위안화 환율은 0.23% 급락한 6.975위안으로 2024년 9월 이후 최저치. 중국의 12월 PMI는 제조업 및 비제조업 모두 시장 예상 상회. 제조업 PMI는 50.1pt, 비제조업 PMI는 50.2pt로 모두 기준치 50pt 상회. 선진국 통화는 유로화 강세, 엔화 약세로 상이한 퍼포먼스 [마켓 이슈] 수급 불균형은 겉으로 드러난 '증상', 한미 성장 격차가 '근본' 2025년 고환율의 배경으로 해외투자 확대에 따른 달러 수요 우위, 즉 수급 불균형이 지적. 다만 이러한 수급 불균형은 고환율의 '원인'이라기보다는 고환율과 함께 동반된 '증상'에 가깝다는 판단. 고환율의 근본적인 원인은 한미 간 잠재성장률 격차의 구조적 확대에 있음. 각국 잠재성장률은 그 나라의 장기 투자수익률을 대변하는 변수. 그리고 수익률이 더 높은 곳으로 자본이 이동하는 것이 자본시장의 기본 메커니즘. 실제 한미 잠재성장률은 2020년 전후로 역전된 이후 그 격차가 지속 확대. 한국 잠재성장률은 인구감소 및 생산성 둔화 등에 하락세. 반면 미국은 이민자 유입과 AI 등 생산성 향상 기대가 성장 잠재력을 지지 중. 이 같은 잠재성장률 격차는 금리 및 자산 기대수익률 차이로 이어지고, 이는 달러 수요 우위의 원화 약세라는 결과로 반영. 즉, 한국의 성장 잠재력 제고 없이는 원화 약세 역시 구조적으로 고착화될 가능성이 크다는 판단 | F3236: 성장하는 곳에 돈이 머문다 [금일 달러/원 환율 1,437~1,443원 전망] | G3236: 이민혁 | H3236: 1437 | I3236: 1443 | J3236: =IFERROR(AVERAGE(H3236:I3236),"") -> 1440 | K3236: =IFERROR(I3236-H3236,"") -> 6
A3237: 46027 | B3237: 46027 | C3237: 0.36805556 | D3237: UTC+9 | E3237: [달러/원 환율] 글로벌 강 달러, 지정학 이벤트에 일시적 상방 변동 예상 전일 달러/원 환율은 일본 엔화 약세 연동 및 저가 매수세 유입에 소폭 상승 개장한 뒤 1,440원대 초반에서 박스권 등락. 장중 미 달러화가 약세를 보이고, 외국인의 국내 주식 순매수세 등에도 불구하고, 결제수요 등 달러 매수가 우위를 보이며 상방 우세 흐름, 전일 종가 대비 2.8원 상승한 1,441.8원에 정규장 마감. 야간장에서는 강 달러 및 저가 매수에 1,450원까지 상승하기도 했으나, 장 막판 상승 폭을 일부 되돌리며 1,444.7원에 마감. 역외 NDF 환율은 0.30원 상승한 1,440.65원에 최종 호가 금일 달러/원 환율은 주말간 달러 강세와 역외 거래 감안해 1,440원대 중반에서 상승 개장 예상. 유로존 제조업황 부진에 따른 유로화 약세가 글로벌 달러 강세 자극. 이에 달러/원도 상승 압력 받으며 1,440원대에서 등락 예상. 더불어 이란 및 베네수엘라 등에서 발생한 지정학 이벤트가 원화 약세 자극할 소지. 다만, 해당 이벤트의 글로벌 시장 파급력은 제한적. 따라서 달러/원의 변동성도 일시에 그칠 것으로 예상 [글로벌 동향] 유로존 제조업 경기 부진이 강 달러 자극, 위안화도 강세 전일 미 달러화는 유로존 제조업황 부진에 따른 유로화 절하 등에 강세. 주요 6개국 통화로 구성된 달러화 지수는 0.16% 상승한 98.45pt 기록. 유로존의 12월 제조업 PMI 확정치는 48.8pt로 예비치인 49.2pt 하회. 이는 2025년 3월의 48.6pt 이후 최저치로, 유로존 경기회복이 지연되고 있음을 시사. 이에 유로/달러 환율은 0.23% 하락하며 1.17달러 부근에서 등락. 파운드화 역시 유로화 약세에 동조, 파운드/달러 환율은 0.12% 하락. 일본 엔화도 선진국 통화 약세에 일부 동조했으나, 외환당국 구두 개입 경계에 약세 폭은 제한적. 중국 위안화는 미 달러화 강세에도 불구하고 절상 흐름 지속. 역외 달러/위안 환율은 0.19% 하락한 6.97위안으로 2023년 5월 이후 최저치. 미 국채금리는 장기물 중심 상승, 뉴욕증시는 새해 첫 거래에서 기술주 부진에 3대 지수 혼조 마감. 한편 주말간 중동과 남미에서 지정학적 이벤트들이 발생 [마켓 이슈] 연초부터 불거진 지정학 이벤트들, 하지만 시장 영향은 제한적 새해 초부터 중동과 남미에서 지정학적 이벤트가 연이어 발생. 이란에서는 경제난을 배경으로 한 반정부 시위가 확산. 베네수엘라는 미국의 무력 침공으로 인해 긴장이 고조되는 상황. 다만 해당 이벤트가 유가 급등 등 시장에 미칠 파급력은 제한적이라는 판단. 우선 이란 사태는 내부 갈등이 표면화된 사건에 불과. 즉, 해당 사태의 중동 전역 확산이나 호르무즈 해협 등 주요 원유 운송로 차질이 발생할 가능성은 제한적. 한편 베네수엘라의 글로벌 경제 및 교역 비중은 매우 낮고, 금융시장에서의 존재감도 미미. 또한 이란과 베네수엘라의 원유 생산 비중은 전세계의 약 5% 수준. 즉 두 국가에서의 원유 공급 차질이 국제유가를 추세적으로 끌어올리긴 역부족. 원화는 글로벌 리스크에 민감한 통화라는 점에서 단기적으로는 영향을 받을 가능성. 하지만 해당 이벤트들의 성격을 종합하면 달러/원의 변동성이 유의미하게 확대될 가능성은 크지 않다는 판단 | F3237: 꿈틀대는 대외 변수들, 원화 약세는 일시적 [금일 달러/원 환율 1,439~1,447원 전망] | G3237: 이민혁 | H3237: 1439 | I3237: 1447 | J3237: =IFERROR(AVERAGE(H3237:I3237),"") -> 1443 | K3237: =IFERROR(I3237-H3237,"") -> 8
A3238: 46028 | B3238: 46028 | C3238: 0.36805556 | D3238: UTC+9 | E3238: [달러/원 환율] 약 달러 및 위험선호에 하락 조정, 저가 매수가 하단 지지 전일 달러/원 환율은 미국의 베네수엘라 침공에 따른 위험회피와 달러 강세에 상승 개장. 장중 달러 추가 강세에 환율도 1,449원까지 추가 상승. 하지만 KOSPI 3% 이상 급등 및 외국인의 국내주식 대거 순매수가 상방 제약. 오후장에서는 레벨 부담에 상승 폭 축소되며 전일 종가 대비 2.0원 상승한 1,443.8원에 정규장 마감. 야간장에서는 저가 매수에 반등한 이후 미 제조업 부진 및 약 달러에 상승 폭 되돌리며 1,445.6원에 마감. 역외 NDF 환율은 1.45원 상승한 1,443.80원에 최종 호가 금일 달러/원 환율은 간밤 달러 약세 및 역외 거래 감안해 보합권에서 개장 예상. 미국 제조업 부진에 따른 국채금리 하락과 성장 추정치 하향에 달러 약세. 반면 뉴욕증시는 베네수엘라 이벤트에 반등하며 위험선호 분위기. 이 같은 약 달러 및 위험선호 조합에 원화 강세 전환 기대. 다만 국내증시와 원화 연계성 약화로 달러/원 하락 폭 제한적일 가능성. 더불어 지속 유입되는 저가 매수세가 하단 지지할 전망 [글로벌 동향] 미 제조업 부진에 달러와 국채금리 하락, 성장 추정치 하향 전일 미 달러화는 미국 제조업황 부진 영향에 약세 전환. 주요 6개국 통화로 구성된 달러화 지수는 0.16% 하락한 98.29pt 기록. 미국 공급관리협회 (ISM) 12월 제조업 지수는 47.9pt 기록. 기준치 50pt를 10개월 연속 하회, 예상치 48.4pt도 소폭 하회. 하위 지수별로는 생산 (51.0pt)과 가격 (58.5pt)이 기준치 상회. 반면 고용 (44.9pt), 신규 주문 (47.7pt), 재고 (45.2pt)는 위축 국면. 애틀랜타 연은 GDPNow는 제조업 지수 반영해 4분기 성장률 추정치를 2.7%로 0.3%p 하향. PCE 증가율은 2.7%에서 2.4%로, 투자 증가율은 7.0%에서 6.5%로 하향. 미 국채금리 역시 제조업황 부진을 반영하며 장단기물 대체로 하락. 뉴욕증시는 미국 정유사들의 베네수엘라 진출 기대에 3대 지수 상승 마감. 닐 카시카리 총재의 발언은 달러와 국채금리 낙폭을 일부 제약. 그는 현재가 중립금리 수준으로 추정된다며 추가 인하에 대해서 신중한 입장 표출 [마켓 이슈] 미국 경제성장의 무게중심 이동: 개인소비지출에서 AI 투자로 미국 경제는 2025년 1~3분기 동안 전기비 연율 기준 평균 2.5%의 성장률을 기록. 겉으로 보면 견조한 성장 흐름이 유지되고 있으나, 성장 구성 내역은 과거와는 달라진 모습. 2025년 미국 성장에서 AI 관련 투자 기여도는 평균 0.9%p로, 전체 성장률의 36.4% 차지. 이는 2024년 AI 투자 기여도 0.2%p (9.6%)보다 비중이 급격히 확대. 반면 전통적인 성장 동력인 개인소비지출 평균 기여도는 1.5%p로, 전체 경제성장의 59.9% 차지. 이는 2024년 기여도 2.3%p (94.3%)에서 뚜렷하게 낮아진 수준. 즉, 최근 미국 경제성장은 AI 투자 의존도가 크게 높아진 형태로 전환. 이 같은 성장 비중 변화는 최근 시장에서 제기되는 AI 버블 논란과도 연결. 만약 향후 AI 과잉 투자 관련 논란이 확산되며 투자지출의 조정이 발생할 경우, 미국 경제에 미칠 충격은 과거보다 훨씬 커질 가능성. 따라서 AI 투자 지속 가능성이 미국 경제성장 경로의 관전 포인트 | F3238: 美 경기 꺾일 때마다 따라붙는 저가 매수 [금일 달러/원 환율 1,438~1,446원 전망] | G3238: 이민혁 | H3238: 1438 | I3238: 1446 | J3238: =IFERROR(AVERAGE(H3238:I3238),"") -> 1442 | K3238: =IFERROR(I3238-H3238,"") -> 8
A3239: 46029 | B3239: 46029 | C3239: 0.36805556 | D3239: UTC+9 | E3239: [달러/원 환율] AI 낙관론 등 위험선호에도 유로화 약세 동조에 혼조세 전일 달러/원 환율은 미국 제조업 지수 부진에도 불구하고 장초반 글로벌 달러 반등과 저가 매수에 1,449원까지 상승. 하지만 이후 달러가 재차 약세로 전환한 가운데, 정부 개입 경계 등에 장중 일시적으로 하락 전환. 오후장에서는 외국인의 국내주식 순매도 등 수급 부담에 하단 지지되며 전일 종가 대비 1.6원 상승한 1,445.4원에 정규장 마감. 야간장에서는 유로화 약세 등 글로벌 강 달러에 상승하며 1,447.1원에 마감. 역외 NDF 환율은 2.25원 상승한 1,446.30원에 최종 호가 금일 달러/원 환율은 간밤 달러 강세와 역외 거래 감안해 1,440원대 중후반에서 개장 예상. 당국 개입 경계가 작용하며 1,450원 부근에서는 추가 상방이 억제. 더불어 AI 낙관론 속 위험선호심리 역시 원화에 긍정적인 요인으로 작용. 장중 외국인 국내주식 플로우에 따라 하락 전환도 가능. 다만 유로發 글로벌 강 달러와 저가 매수가 달러/원 상방 자극. 금일 환율은 위험선호심리 회복에도 유로화 약세 동조에 혼조 예상 [글로벌 동향] 유로존 경기 부진 및 독일 물가 우려 완화에 미 달러 강세 전일 미 달러화는 유로화 부진 속 반발 매수에 강세 전환. 주요 6개국 통화로 구성된 달러화 지수는 0.31% 상승한 98.60pt 기록. 뉴욕증시는 AI 낙관론 속 3대 지수 모두 상승하며 위험선호 분위기. 하지만 유로화는 유로존 경기 부진 및 독일 물가 우려 완화 등에 약세. 유로존 12월 PMI 확정치는 51.5pt로 직전치 (52.8pt)와 예비치 (51.9pt) 모두 하회. 기준치인 50pt는 상회하며 확장 국면이었으나, 그 모멘텀은 약화된 것으로 확인. 독일 물가지표 발표 이후 유로/달러는 1.17달러 하회하며 약세 폭 확대. 독일의 12월 소비자물가지수는 전년비 1.8% 상승에 그치며 예상치 (+2.1%) 하회. 이에 독일 분트 금리가 일제히 하락하며 유로화 약세로 연결. 스티븐 마이런 이사는 올해 100bp 인하의 정당성을 주장. 그는 지나치게 제약적인 통화정책은 성장 동력을 약화시킬 수 있다고 지적. 하지만 미 국채금리는 해당 발언에도 불구, 회사채 수급 부담에 상승 [마켓 이슈] 베네수엘라 사태는 표면, 미국發 지정학 리스크가 사태의 본질 베네수엘라 사태는 단기적으로 시장에 호재로 인식되는 분위기. 국제유가는 안정적인 가운데, 글로벌 증시는 안도 랠리. 다만 문제는 '지금의 베네수엘라'가 아닌 '앞으로의 미국'. 이번 사태는 미국의 공격적 외교·안보 스탠스가 다시 전면에 부상하고 있음을 알린 신호. 실제로 지정학적 리스크 지수는 이번 사태를 계기로 6개월 만에 최고치를 기록. 이는 지난해 6월 미국의 이란 무력 개입 당시 이후로 가장 높은 레벨. 이 같은 미국의 일방적 무력 사용은 중국과 러시아 등 전략적 경쟁국을 자극할 수 있는 사안. 이로 인해 외교 갈등이 불거짐과 더불어 다시 관세 전쟁, 기술 제재 등 경제적 충돌이 발생할 가능성. 이 과정에서 한국 원화의 취약성이 다시 부각될 가능성도 상존. 원화는 대외 변수에 민감하게 반응하는 대표적인 '위험 통화' 중 하나. 이번 사태로 인해 향후 지정학적 갈등이 심화할 경우, 원화 역시 변동성이 확대될 리스크에 유의 | F3239: 다 된 밥에 유로화 약세 뿌리기 [금일 달러/원 환율 1,443~1,450원 전망] | G3239: 이민혁 | H3239: 1443 | I3239: 1450 | J3239: =IFERROR(AVERAGE(H3239:I3239),"") -> 1446.5 | K3239: =IFERROR(I3239-H3239,"") -> 7
A3240: 46030 | B3240: 46030 | C3240: 0.36805556 | D3240: UTC+9 | E3240: [달러/원 환율] 미 고용 등 누적되는 약 달러 압력, 장중 하락 전환 예상 전일 달러/원 환율은 유로화 약세에 동조해 상승 개장한 이후 저가 매수까지 가세하며 1,449원까지 추가 상승. 하지만 당국 개입 경계에 1,450원 상회는 실패하며 상승 폭 일부 축소. 이후 외국인의 국내주식 순매수 등에 장막판 대부분의 상승 분을 되돌리며, 전일 종가 대비 0.4원 상승한 1,445.8원에 정규장 마감. 야간장에서는 미국 서비스업 호조에 따른 달러 강세와 유로화 약세에 소폭 상승하며 1,447.6원에 마감. 역외 NDF 환율은 4.00원 상승한 1,448.40원에 최종 호가 금일 달러/원 환율은 간밤 달러 강세와 역외 거래 감안해 1,440원대 중후반에서 개장 예상. 미 서비스업 호조 및 독일 소비 둔화가 글로벌 달러 반등 자극. 이에 달러/원도 하방 제약된 가운데, 당국 경계에 박스권 등락 예상. 하지만 미 고용지표 부진에 달러 약세 압력 역시 가중되는 상황. 장중 글로벌 달러 약세 전환 시, 달러/원도 하락 동조 가능하다는 판단. 금일 환율은 1,450원이 심리적 상단인 가운데, 하방 압력 받을 전망 [글로벌 동향] 美 고용 부진에도 서비스업 호조, 獨 소비 둔화에 강 달러 전일 미 달러화는 미국 고용지표 부진에도 독일 경기둔화 우려 등에 강세. 주요 6개국 통화로 구성된 달러화 지수는 0.11% 상승한 98.71pt 기록. 전일 저녁 발표된 미국 고용지표는 시장 예상보다 부진. ADP의 12월 민간고용은 4.1만명 증가하며 전월치 (- 2.9만명)보다는 개선. 하지만 예상치 +5.0만명은 하회, 주로 정보 및 전문비즈니스 부문에서 부진. JOLTs의 11월 구인건수는 714만건으로 전월치 (745만건)과 예상치 (765만건) 모두 하회. 이는 2024년 9월 이후 최저 수준으로, 노동수요의 둔화 시사. 11월 구인율은 4.3%로 전월대비 0.2%p 하락. 하지만 미국 서비스업황 호조가 고용 부진 영향 상쇄. 12월 ISM 서비스업 지수는 54.4pt로 2025년 중 최고치 기록. 한편 유로화는 독일 소비 둔화와 분트 금리 하락에 약세. 독일의 11월 소매판매는 전월대비 0.6% 감소. 이에 독일 분트 금리가 3거래일 연속 하락하며 유로화 약세에 기여 [마켓 이슈] 관세 충격은 인플레이션이 아닌 디스인플레이션 유발 (FRBSF) 샌프란시스코 연은에 따르면, 대규모의 관세 인상이 실업률 상승 및 물가 압력 둔화를 유발한 것으로 분석 (FRBSF ECONOMIC LETTER 2026-01). 19세기 말~20세기 초의 관세 인상 사례를 분석한 결과, 관세 충격은 비용 상승보다는 불확실성 확대 및 총수요 위축을 통해 디스인플레이션으로 연결. 이러한 역사적 분석 결과를 현재 미국 경제 상황에 대입해보면, 향후 실업률은 추가 상승 여지, 물가상승률은 시장 예상보다 더 낮아질 것으로 예상. 이 경우 연준 통화정책 목표에서 물가보다는 고용 안정에 대한 가중치가 더욱 확대. 연준의 금리경로 역시 기존보다 더욱 완화적으로 이동할 가능성. 즉 물가 불안이 크지 않은 상황에서 고용 둔화가 심화될수록, 연준의 금리인하 명분은 더욱 강화되고 달러 약세 압력 역시 가중될 것으로 예상. 따라서 금주, 차주에 발표될 고용 및 물가지표 결과, 이에 따른 연준 금리경로 기대 변화에 주목할 필요 | F3240: 미 고용은 탄광 속 카나리아, 달러 반등은 잠깐 [금일 달러/원 환율 1,443~1,451원 전망] | G3240: 이민혁 | H3240: 1443 | I3240: 1451 | J3240: =IFERROR(AVERAGE(H3240:I3240),"") -> 1447 | K3240: =IFERROR(I3240-H3240,"") -> 8
...

Sheet view
A1: =IF(USDKRW!B1="","",USDKRW!B1) -> Release Date | B1: =IF(USDKRW!H1="","",USDKRW!H1) -> USDKRW Lower | C1: =IF(USDKRW!I1="","",USDKRW!I1) -> USDKRW Upper | D1: Base | E1: =IF(USDKRW!J1="","",USDKRW!J1) -> USDKRW Median | F1: =IF(OR(USDKRW!K1="",USDKRW!K1=0),"",USDKRW!K1) -> USDKRW Range
A2: =IF(USDKRW!B2="","",USDKRW!B2) -> 42738 | B2: =IF(USDKRW!H2="","",USDKRW!H2) | C2: =IF(USDKRW!I2="","",USDKRW!I2) | D2: =B2 | E2: =IF(USDKRW!J2="","",USDKRW!J2) | F2: =IF(OR(USDKRW!K2="",USDKRW!K2=0),"",USDKRW!K2)
A3: =IF(USDKRW!B3="","",USDKRW!B3) -> 42739 | B3: =IF(USDKRW!H3="","",USDKRW!H3) | C3: =IF(USDKRW!I3="","",USDKRW!I3) | D3: =B3 | E3: =IF(USDKRW!J3="","",USDKRW!J3) | F3: =IF(OR(USDKRW!K3="",USDKRW!K3=0),"",USDKRW!K3)
A4: =IF(USDKRW!B4="","",USDKRW!B4) -> 42740 | B4: =IF(USDKRW!H4="","",USDKRW!H4) | C4: =IF(USDKRW!I4="","",USDKRW!I4) | D4: =B4 | E4: =IF(USDKRW!J4="","",USDKRW!J4) | F4: =IF(OR(USDKRW!K4="",USDKRW!K4=0),"",USDKRW!K4)
A5: =IF(USDKRW!B5="","",USDKRW!B5) -> 42741 | B5: =IF(USDKRW!H5="","",USDKRW!H5) | C5: =IF(USDKRW!I5="","",USDKRW!I5) | D5: =B5 | E5: =IF(USDKRW!J5="","",USDKRW!J5) | F5: =IF(OR(USDKRW!K5="",USDKRW!K5=0),"",USDKRW!K5)
A6: =IF(USDKRW!B6="","",USDKRW!B6) -> 42744 | B6: =IF(USDKRW!H6="","",USDKRW!H6) | C6: =IF(USDKRW!I6="","",USDKRW!I6) | D6: =B6 | E6: =IF(USDKRW!J6="","",USDKRW!J6) | F6: =IF(OR(USDKRW!K6="",USDKRW!K6=0),"",USDKRW!K6)
A7: =IF(USDKRW!B7="","",USDKRW!B7) -> 42745 | B7: =IF(USDKRW!H7="","",USDKRW!H7) | C7: =IF(USDKRW!I7="","",USDKRW!I7) | D7: =B7 | E7: =IF(USDKRW!J7="","",USDKRW!J7) | F7: =IF(OR(USDKRW!K7="",USDKRW!K7=0),"",USDKRW!K7)
A8: =IF(USDKRW!B8="","",USDKRW!B8) -> 42746 | B8: =IF(USDKRW!H8="","",USDKRW!H8) | C8: =IF(USDKRW!I8="","",USDKRW!I8) | D8: =B8 | E8: =IF(USDKRW!J8="","",USDKRW!J8) | F8: =IF(OR(USDKRW!K8="",USDKRW!K8=0),"",USDKRW!K8)
A9: =IF(USDKRW!B9="","",USDKRW!B9) -> 42747 | B9: =IF(USDKRW!H9="","",USDKRW!H9) | C9: =IF(USDKRW!I9="","",USDKRW!I9) | D9: =B9 | E9: =IF(USDKRW!J9="","",USDKRW!J9) | F9: =IF(OR(USDKRW!K9="",USDKRW!K9=0),"",USDKRW!K9)
A10: =IF(USDKRW!B10="","",USDKRW!B10) -> 42748 | B10: =IF(USDKRW!H10="","",USDKRW!H10) | C10: =IF(USDKRW!I10="","",USDKRW!I10) | D10: =B10 | E10: =IF(USDKRW!J10="","",USDKRW!J10) | F10: =IF(OR(USDKRW!K10="",USDKRW!K10=0),"",USDKRW!K10)
A11: =IF(USDKRW!B11="","",USDKRW!B11) -> 42749 | B11: =IF(USDKRW!H11="","",USDKRW!H11) | C11: =IF(USDKRW!I11="","",USDKRW!I11) | D11: =B11 | E11: =IF(USDKRW!J11="","",USDKRW!J11) | F11: =IF(OR(USDKRW!K11="",USDKRW!K11=0),"",USDKRW!K11)
A12: =IF(USDKRW!B12="","",USDKRW!B12) -> 42750 | B12: =IF(USDKRW!H12="","",USDKRW!H12) | C12: =IF(USDKRW!I12="","",USDKRW!I12) | D12: =B12 | E12: =IF(USDKRW!J12="","",USDKRW!J12) | F12: =IF(OR(USDKRW!K12="",USDKRW!K12=0),"",USDKRW!K12)
A13: =IF(USDKRW!B13="","",USDKRW!B13) -> 42751 | B13: =IF(USDKRW!H13="","",USDKRW!H13) | C13: =IF(USDKRW!I13="","",USDKRW!I13) | D13: =B13 | E13: =IF(USDKRW!J13="","",USDKRW!J13) | F13: =IF(OR(USDKRW!K13="",USDKRW!K13=0),"",USDKRW!K13)
... A3234: =IF(USDKRW!B3234="","",USDKRW!B3234) -> 46021 | B3234: =IF(USDKRW!H3234="","",USDKRW!H3234) -> 1425 | C3234: =IF(USDKRW!I3234="","",USDKRW!I3234) -> 1436 | D3234: =B3234 -> 1425 | E3234: =IF(USDKRW!J3234="","",USDKRW!J3234) -> 1430.5 | F3234: =IF(OR(USDKRW!K3234="",USDKRW!K3234=0),"",USDKRW!K3234) -> 11
A3235: =IF(USDKRW!B3235="","",USDKRW!B3235) -> 46022 | B3235: 1425 | C3235: 1436 | D3235: 1425 | E3235: =IF(USDKRW!J3235="","",USDKRW!J3235) -> 1430.5 | F3235: 11
A3236: =IF(USDKRW!B3236="","",USDKRW!B3236) -> 46024 | B3236: =IF(USDKRW!H3236="","",USDKRW!H3236) -> 1437 | C3236: =IF(USDKRW!I3236="","",USDKRW!I3236) -> 1443 | D3236: =B3236 -> 1437 | E3236: =IF(USDKRW!J3236="","",USDKRW!J3236) -> 1440 | F3236: =IF(OR(USDKRW!K3236="",USDKRW!K3236=0),"",USDKRW!K3236) -> 6
A3237: =IF(USDKRW!B3237="","",USDKRW!B3237) -> 46027 | B3237: =IF(USDKRW!H3237="","",USDKRW!H3237) -> 1439 | C3237: =IF(USDKRW!I3237="","",USDKRW!I3237) -> 1447 | D3237: =B3237 -> 1439 | E3237: =IF(USDKRW!J3237="","",USDKRW!J3237) -> 1443 | F3237: =IF(OR(USDKRW!K3237="",USDKRW!K3237=0),"",USDKRW!K3237) -> 8
A3238: =IF(USDKRW!B3238="","",USDKRW!B3238) -> 46028 | B3238: =IF(USDKRW!H3238="","",USDKRW!H3238) -> 1438 | C3238: =IF(USDKRW!I3238="","",USDKRW!I3238) -> 1446 | D3238: =B3238 -> 1438 | E3238: =IF(USDKRW!J3238="","",USDKRW!J3238) -> 1442 | F3238: =IF(OR(USDKRW!K3238="",USDKRW!K3238=0),"",USDKRW!K3238) -> 8
A3239: =IF(USDKRW!B3239="","",USDKRW!B3239) -> 46029 | B3239: =IF(USDKRW!H3239="","",USDKRW!H3239) -> 1443 | C3239: =IF(USDKRW!I3239="","",USDKRW!I3239) -> 1450 | D3239: =B3239 -> 1443 | E3239: =IF(USDKRW!J3239="","",USDKRW!J3239) -> 1446.5 | F3239: =IF(OR(USDKRW!K3239="",USDKRW!K3239=0),"",USDKRW!K3239) -> 7
A3240: =IF(USDKRW!B3240="","",USDKRW!B3240) -> 46030 | B3240: =IF(USDKRW!H3240="","",USDKRW!H3240) -> 1443 | C3240: =IF(USDKRW!I3240="","",USDKRW!I3240) -> 1451 | D3240: =B3240 -> 1443 | E3240: =IF(USDKRW!J3240="","",USDKRW!J3240) -> 1447 | F3240: =IF(OR(USDKRW!K3240="",USDKRW!K3240=0),"",USDKRW!K3240) -> 8
A3241: =IF(USDKRW!B3241="","",USDKRW!B3241) -> 46031 | B3241: =IF(USDKRW!H3241="","",USDKRW!H3241) -> 1449 | C3241: =IF(USDKRW!I3241="","",USDKRW!I3241) -> 1455 | D3241: =B3241 -> 1449 | E3241: =IF(USDKRW!J3241="","",USDKRW!J3241) -> 1452 | F3241: =IF(OR(USDKRW!K3241="",USDKRW!K3241=0),"",USDKRW!K3241) -> 6
A3242: =IF(USDKRW!B3242="","",USDKRW!B3242) -> 46034 | B3242: =IF(USDKRW!H3242="","",USDKRW!H3242) -> 1455 | C3242: =IF(USDKRW!I3242="","",USDKRW!I3242) -> 1462 | D3242: =B3242 -> 1455 | E3242: =IF(USDKRW!J3242="","",USDKRW!J3242) -> 1458.5 | F3242: =IF(OR(USDKRW!K3242="",USDKRW!K3242=0),"",USDKRW!K3242) -> 7
A3243: =IF(USDKRW!B3243="","",USDKRW!B3243) -> 46035 | B3243: =IF(USDKRW!H3243="","",USDKRW!H3243) -> 1462 | C3243: =IF(USDKRW!I3243="","",USDKRW!I3243) -> 1470 | D3243: =B3243 -> 1462 | E3243: =IF(USDKRW!J3243="","",USDKRW!J3243) -> 1466 | F3243: =IF(OR(USDKRW!K3243="",USDKRW!K3243=0),"",USDKRW!K3243) -> 8
A3244: =IF(USDKRW!B3244="","",USDKRW!B3244) -> 46036 | B3244: =IF(USDKRW!H3244="","",USDKRW!H3244) -> 1470 | C3244: =IF(USDKRW!I3244="","",USDKRW!I3244) -> 1479 | D3244: =B3244 -> 1470 | E3244: =IF(USDKRW!J3244="","",USDKRW!J3244) -> 1474.5 | F3244: =IF(OR(USDKRW!K3244="",USDKRW!K3244=0),"",USDKRW!K3244) -> 9
A3245: =IF(USDKRW!B3245="","",USDKRW!B3245) -> 46037 | B3245: =IF(USDKRW!H3245="","",USDKRW!H3245) -> 1457 | C3245: =IF(USDKRW!I3245="","",USDKRW!I3245) -> 1470 | D3245: =B3245 -> 1457 | E3245: =IF(USDKRW!J3245="","",USDKRW!J3245) -> 1463.5 | F3245: =IF(OR(USDKRW!K3245="",USDKRW!K3245=0),"",USDKRW!K3245) -> 13
A3246: =IF(USDKRW!B3246="","",USDKRW!B3246) -> 46038 | B3246: =IF(USDKRW!H3246="","",USDKRW!H3246) -> 1467 | C3246: =IF(USDKRW!I3246="","",USDKRW!I3246) -> 1475 | D3246: =B3246 -> 1467 | E3246: =IF(USDKRW!J3246="","",USDKRW!J3246) -> 1471 | F3246: =IF(OR(USDKRW!K3246="",USDKRW!K3246=0),"",USDKRW!K3246) -> 8
A3247: =IF(USDKRW!B3247="","",USDKRW!B3247) -> 46041 | B3247: =IF(USDKRW!H3247="","",USDKRW!H3247) -> 1470 | C3247: =IF(USDKRW!I3247="","",USDKRW!I3247) -> 1478 | D3247: =B3247 -> 1470 | E3247: =IF(USDKRW!J3247="","",USDKRW!J3247) -> 1474 | F3247: =IF(OR(USDKRW!K3247="",USDKRW!K3247=0),"",USDKRW!K3247) -> 8
... A3359: =IF(USDKRW!B3359="","",USDKRW!B3359) | B3359: =IF(USDKRW!H3359="","",USDKRW!H3359) | C3359: =IF(USDKRW!I3359="","",USDKRW!I3359) | D3359: =B3359 | E3359: =IF(USDKRW!J3359="","",USDKRW!J3359) | F3359: =IF(OR(USDKRW!K3359="",USDKRW!K3359=0),"",USDKRW!K3359)
A3360: =IF(USDKRW!B3353="","",USDKRW!B3353) -> 46199 | B3360: =IF(USDKRW!H3353="","",USDKRW!H3353) -> 1535 | C3360: =IF(USDKRW!I3353="","",USDKRW!I3353) -> 1547 | D3360: =B3360 -> 1535 | E3360: =IF(USDKRW!J3353="","",USDKRW!J3353) -> 1541 | F3360: =IF(OR(USDKRW!K3353="",USDKRW!K3353=0),"",USDKRW!K3353) -> 12
A3361: =IF(USDKRW!B3354="","",USDKRW!B3354) -> 46202 | B3361: =IF(USDKRW!H3354="","",USDKRW!H3354) -> 1530 | C3361: =IF(USDKRW!I3354="","",USDKRW!I3354) -> 1545 | D3361: =B3361 -> 1530 | E3361: =IF(USDKRW!J3354="","",USDKRW!J3354) -> 1537.5 | F3361: =IF(OR(USDKRW!K3354="",USDKRW!K3354=0),"",USDKRW!K3354) -> 15
A3362: =IF(USDKRW!B3355="","",USDKRW!B3355) -> 46203 | B3362: =IF(USDKRW!H3355="","",USDKRW!H3355) -> 1530 | C3362: =IF(USDKRW!I3355="","",USDKRW!I3355) -> 1550 | D3362: =B3362 -> 1530 | E3362: =IF(USDKRW!J3355="","",USDKRW!J3355) -> 1540 | F3362: =IF(OR(USDKRW!K3355="",USDKRW!K3355=0),"",USDKRW!K3355) -> 20
A3363: =IF(USDKRW!B3356="","",USDKRW!B3356) -> 46204 | B3363: =IF(USDKRW!H3356="","",USDKRW!H3356) -> 1535 | C3363: =IF(USDKRW!I3356="","",USDKRW!I3356) -> 1550 | D3363: =B3363 -> 1535 | E3363: =IF(USDKRW!J3356="","",USDKRW!J3356) -> 1542.5 | F3363: =IF(OR(USDKRW!K3356="",USDKRW!K3356=0),"",USDKRW!K3356) -> 15
A3364: =IF(USDKRW!B3357="","",USDKRW!B3357) -> 46205 | B3364: =IF(USDKRW!H3357="","",USDKRW!H3357) -> 1545 | C3364: =IF(USDKRW!I3357="","",USDKRW!I3357) -> 1557 | D3364: =B3364 -> 1545 | E3364: =IF(USDKRW!J3357="","",USDKRW!J3357) -> 1551 | F3364: =IF(OR(USDKRW!K3357="",USDKRW!K3357=0),"",USDKRW!K3357) -> 12
A3365: =IF(USDKRW!B3358="","",USDKRW!B3358) | B3365: =IF(USDKRW!H3358="","",USDKRW!H3358) | C3365: =IF(USDKRW!I3358="","",USDKRW!I3358) | D3365: =B3365 | E3365: =IF(USDKRW!J3358="","",USDKRW!J3358) | F3365: =IF(OR(USDKRW!K3358="",USDKRW!K3358=0),"",USDKRW!K3358)
A3366: =IF(USDKRW!B3359="","",USDKRW!B3359) | B3366: =IF(USDKRW!H3359="","",USDKRW!H3359) | C3366: =IF(USDKRW!I3359="","",USDKRW!I3359) | D3366: =B3366 | E3366: =IF(USDKRW!J3359="","",USDKRW!J3359) | F3366: =IF(OR(USDKRW!K3359="",USDKRW!K3359=0),"",USDKRW!K3359)
A3367: =IF(USDKRW!B3360="","",USDKRW!B3360) | B3367: =IF(USDKRW!H3360="","",USDKRW!H3360) | C3367: =IF(USDKRW!I3360="","",USDKRW!I3360) | D3367: =B3367 | E3367: =IF(USDKRW!J3360="","",USDKRW!J3360) | F3367: =IF(OR(USDKRW!K3360="",USDKRW!K3360=0),"",USDKRW!K3360)
A3368: =IF(USDKRW!B3361="","",USDKRW!B3361) | B3368: =IF(USDKRW!H3361="","",USDKRW!H3361) | C3368: =IF(USDKRW!I3361="","",USDKRW!I3361) | D3368: =B3368 | E3368: =IF(USDKRW!J3361="","",USDKRW!J3361) | F3368: =IF(OR(USDKRW!K3361="",USDKRW!K3361=0),"",USDKRW!K3361)
A3369: =IF(USDKRW!B3362="","",USDKRW!B3362) | B3369: =IF(USDKRW!H3362="","",USDKRW!H3362) | C3369: =IF(USDKRW!I3362="","",USDKRW!I3362) | D3369: =B3369 | E3369: =IF(USDKRW!J3362="","",USDKRW!J3362) | F3369: =IF(OR(USDKRW!K3362="",USDKRW!K3362=0),"",USDKRW!K3362)
A3370: =IF(USDKRW!B3363="","",USDKRW!B3363) | B3370: =IF(USDKRW!H3363="","",USDKRW!H3363) | C3370: =IF(USDKRW!I3363="","",USDKRW!I3363) | D3370: =B3370 | E3370: =IF(USDKRW!J3363="","",USDKRW!J3363) | F3370: =IF(OR(USDKRW!K3363="",USDKRW!K3363=0),"",USDKRW!K3363)
A3371: =IF(USDKRW!B3364="","",USDKRW!B3364) | B3371: =IF(USDKRW!H3364="","",USDKRW!H3364) | C3371: =IF(USDKRW!I3364="","",USDKRW!I3364) | D3371: =B3371 | E3371: =IF(USDKRW!J3364="","",USDKRW!J3364) | F3371: =IF(OR(USDKRW!K3364="",USDKRW!K3364=0),"",USDKRW!K3364)
...

Sheet fig

Sheet info
B2: Source | C2: https://obank.kbstar.com/quics?page=C101425#loading
B3: Frequency | C3: Daily
